Workbook

Sheet Workforce
A1: Agent Name | B1: Position | C1: Start Date
A2: Ben Arthur | B2: Full-Time
A3: Jimmy Pearson | B3: Full-Time
A4: Kaity James | B4: Part-Time | C4: 46262
A5: Selene Myles | B5: Full-Time
A6: Mohamed | B6: Full-Time
A7: Malak El Khateeb | B7: Full-Time
A8: Caroline Richards | B8: Full-Time
A9: Rick Nelson | B9: Full-Time
A10: Nora Atkins | B10: Full-Time
A11: Jasmine Green | B11: Full-Time

Sheet Attendance
A1: Month | B1: =iferror(concatenate(" Enter ", 'Attendance key'!$B$6, " for ",'Attendance key'!$C$6, ", ", 'Attendance key'!$B$7, " for ", 'Attendance key'!$C$7, ", ", 'Attendance key'!$B$8, " for ", 'Attendance key'!$C$8, ", and ", 'Attendance key'!$B$9, " for ", 'Attendance key'!$C$9, ". Use the 'Attendance key' tab to customize. "),"")
A2: Date | B2: 46019 | C2: =B2+1 -> 46020 | D2: =C2+1 -> 46021 | E2: =D2+1 -> 46022 | F2: =E2+1 -> 46023 | G2: =F2+1 -> 46024 | H2: =G2+1 -> 46025 | I2: =H2+1 -> 46026 | J2: =I2+1 -> 46027 | ... AF2: =AE2+1 -> 46049 | AH2: Present | AI2: Late | AK2: Off | AN2: Double paid | AO2: Absent | AP2: N.S.N.C. | AQ2: Training | AR2: Spiffs | AT2: Deductions
A3: Day | B3: =B2 -> 46019 | C3: =C2 -> 46020 | D3: =D2 -> 46021 | E3: =E2 -> 46022 | F3: =F2 -> 46023 | G3: =G2 -> 46024 | H3: =H2 -> 46025 | I3: =I2 -> 46026 | ... AG3: =AG2 | AH3: P | AI3: L1 | AJ3: L2 | AK3: Q | AL3: H | AM3: Off | AN3: D | AO3: A | AP3: N | AQ3: T | AR3: All | AS3: Paid
A4: =Workforce!A2 -> Ben Arthur | B4: Off | C4: Off | D4: Off | E4: Off | F4: Off | G4: Off | H4: Off | I4: Off | J4: H | K4: H | L4: P | M4: H | N4: P | O4: Off | P4: Off | Q4: P | R4: H | S4: P | T4: P | U4: P | V4: Off | W4: Off | X4: P | Y4: H | Z4: P | AA4: H | AB4: P | AC4: Off | AD4: Off | AE4: L2 | AF4: P | AH4: =(countif(B4:AG4,AH$3))+AI4+AJ4+(AL4*0.5)+(AK4*0.75) -> 14 | AI4: =countif(B4:AG4,$AI$3) -> 0 | AJ4: =countif(B4:AG4,AJ$3) -> 1 | AK4: =countif(B4:AG4,AK$3) -> 0 | AL4: =countif(B4:AG4,AL$3) -> 6 | AM4: =countif(B4:AG4,$AM$3) -> 14 | AN4: =countif(B4:AG4,AN$3) -> 0 | AO4: =(countif(B4:AL4,"A")) -> 0 | AP4: =countif(B4:AO4,AP$3) -> 0 | AQ4: =countif(B4:AP4,AQ$3) -> 0 | AR4: =SUMIF('Spiffs & Deductions'!A$3:A1005,A4,'Spiffs & Deductions'!B$3:B1005) -> 0 | AS4: =SUMIFs('Spiffs & Deductions'!B$3:B1005,'Spiffs & Deductions'!A$3:A1005,A4,'Spiffs & Deductions'!C$3:C1005,$AS$3) -> 0 | AT4: =SUMIF('Spiffs & Deductions'!H$4:H1005,A4,'Spiffs & Deductions'!I$4:I1005) -> 0
A5: =Workforce!A3 -> Jimmy Pearson | B5: Off | C5: Off | D5: Off | E5: Off | F5: Off | G5: Off | H5: Off | I5: Off | J5: P | K5: P | L5: P | M5: P | N5: P | O5: Off | P5: Off | Q5: P | R5: P | S5: P | T5: P | U5: P | V5: Off | W5: Off | X5: P | Y5: P | Z5: P | AA5: P | AB5: P | AC5: Off | AD5: Off | AE5: P | AF5: P | AH5: =(countif(B5:AG5,AH$3))+AI5+AJ5+(AL5*0.5)+(AK5*0.75) -> 17 | AI5: =countif(B5:AG5,$AI$3) -> 0 | AJ5: =countif(B5:AG5,AJ$3) -> 0 | AK5: =countif(B5:AG5,AK$3) -> 0 | AL5: =countif(B5:AG5,AL$3) -> 0 | AM5: =countif(B5:AG5,$AM$3) -> 14 | AN5: =countif(B5:AG5,AN$3) -> 0 | AO5: =(countif(B5:AL5,"A")) -> 0 | AP5: =countif(B5:AO5,AP$3) -> 0 | AQ5: =countif(B5:AP5,AQ$3) -> 0 | AR5: =SUMIF('Spiffs & Deductions'!A$3:A1005,A5,'Spiffs & Deductions'!B$3:B1005) -> 0 | AS5: =SUMIFs('Spiffs & Deductions'!B$3:B1005,'Spiffs & Deductions'!A$3:A1005,A5,'Spiffs & Deductions'!C$3:C1005,$AS$3) -> 0 | AT5: =SUMIF('Spiffs & Deductions'!H$4:H1005,A5,'Spiffs & Deductions'!I$4:I1005) -> 0
A6: =Workforce!A4 -> Kaity James | B6: Off | C6: Off | D6: Off | E6: Off | F6: Off | G6: Off | H6: Off | I6: Off | J6: P | K6: P | L6: P | M6: P | N6: P | O6: Off | P6: Off | Q6: P | R6: P | S6: P | T6: Q | U6: P | V6: Off | W6: Off | X6: P | Y6: P | Z6: P | AA6: P | AB6: P | AC6: Off | AD6: Off | AE6: P | AF6: P | AH6: =(countif(B6:AG6,AH$3))+AI6+AJ6+(AL6*0.5)+(AK6*0.75) -> 16.75 | AI6: =countif(B6:AG6,$AI$3) -> 0 | AJ6: =countif(B6:AG6,AJ$3) -> 0 | AK6: =countif(B6:AG6,AK$3) -> 1 | AL6: =countif(B6:AG6,AL$3) -> 0 | AM6: =countif(B6:AG6,$AM$3) -> 14 | AN6: =countif(B6:AG6,AN$3) -> 0 | AO6: =(countif(B6:AL6,"A")) -> 0 | AP6: =countif(B6:AO6,AP$3) -> 0 | AQ6: =countif(B6:AP6,AQ$3) -> 0 | AR6: =SUMIF('Spiffs & Deductions'!A$3:A1005,A6,'Spiffs & Deductions'!B$3:B1005) -> 0 | AS6: =SUMIFs('Spiffs & Deductions'!B$3:B1005,'Spiffs & Deductions'!A$3:A1005,A6,'Spiffs & Deductions'!C$3:C1005,$AS$3) -> 0 | AT6: =SUMIF('Spiffs & Deductions'!H$4:H1005,A6,'Spiffs & Deductions'!I$4:I1005) -> 0
A7: =Workforce!A5 -> Selene Myles | B7: Off | C7: Off | D7: Off | E7: Off | F7: Off | G7: Off | H7: Off | I7: Off | J7: P | K7: P | L7: P | M7: P | N7: P | O7: Off | P7: Off | Q7: P | R7: P | S7: P | T7: P | U7: P | V7: Off | W7: Off | X7: P | Y7: P | Z7: P | AA7: P | AB7: P | AC7: Off | AD7: Off | AE7: P | AF7: P | AH7: =(countif(B7:AG7,AH$3))+AI7+AJ7+(AL7*0.5)+(AK7*0.75) -> 17 | AI7: =countif(B7:AG7,$AI$3) -> 0 | AJ7: =countif(B7:AG7,AJ$3) -> 0 | AK7: =countif(B7:AG7,AK$3) -> 0 | AL7: =countif(B7:AG7,AL$3) -> 0 | AM7: =countif(B7:AG7,$AM$3) -> 14 | AN7: =countif(B7:AG7,AN$3) -> 0 | AO7: =(countif(B7:AL7,"A")) -> 0 | AP7: =countif(B7:AO7,AP$3) -> 0 | AQ7: =countif(B7:AP7,AQ$3) -> 0 | AR7: =SUMIF('Spiffs & Deductions'!A$3:A1005,A7,'Spiffs & Deductions'!B$3:B1005) -> 0 | AS7: =SUMIFs('Spiffs & Deductions'!B$3:B1005,'Spiffs & Deductions'!A$3:A1005,A7,'Spiffs & Deductions'!C$3:C1005,$AS$3) -> 0 | AT7: =SUMIF('Spiffs & Deductions'!H$4:H1005,A7,'Spiffs & Deductions'!I$4:I1005) -> 0
A8: =Workforce!A6 -> Mohamed | B8: Off | C8: Off | D8: Off | E8: Off | F8: Off | G8: Off | H8: Off | I8: Off | J8: P | K8: P | L8: P | M8: P | N8: P | O8: Off | P8: Off | Q8: P | R8: P | S8: P | T8: P | U8: P | V8: Off | W8: Off | X8: P | Y8: P | Z8: P | AA8: P | AB8: P | AC8: Off | AD8: Off | AE8: P | AF8: P | AH8: =(countif(B8:AG8,AH$3))+AI8+AJ8+(AL8*0.5)+(AK8*0.75) -> 17 | AI8: =countif(B8:AG8,$AI$3) -> 0 | AJ8: =countif(B8:AG8,AJ$3) -> 0 | AK8: =countif(B8:AG8,AK$3) -> 0 | AL8: =countif(B8:AG8,AL$3) -> 0 | AM8: =countif(B8:AG8,$AM$3) -> 14 | AN8: =countif(B8:AG8,AN$3) -> 0 | AO8: =(countif(B8:AL8,"A")) -> 0 | AP8: =countif(B8:AO8,AP$3) -> 0 | AQ8: =countif(B8:AP8,AQ$3) -> 0 | AR8: 200 | AS8: =SUMIFs('Spiffs & Deductions'!B$3:B1005,'Spiffs & Deductions'!A$3:A1005,A8,'Spiffs & Deductions'!C$3:C1005,$AS$3) -> 0 | AT8: =SUMIF('Spiffs & Deductions'!H$4:H1005,A8,'Spiffs & Deductions'!I$4:I1005) -> 0
A9: =Workforce!A7 -> Malak El Khateeb | B9: Off | C9: Off | D9: Off | E9: Off | F9: Off | G9: Off | H9: Off | I9: Off | J9: P | K9: P | L9: P | M9: P | N9: P | O9: Off | P9: Off | Q9: P | R9: P | S9: P | T9: P | U9: P | V9: Off | W9: Off | X9: P | Y9: P | Z9: P | AA9: P | AB9: P | AC9: Off | AD9: Off | AE9: P | AF9: P | AH9: =(countif(B9:AG9,AH$3))+AI9+AJ9+(AL9*0.5)+(AK9*0.75) -> 17 | AI9: =countif(B9:AG9,$AI$3) -> 0 | AJ9: =countif(B9:AG9,AJ$3) -> 0 | AK9: =countif(B9:AG9,AK$3) -> 0 | AL9: =countif(B9:AG9,AL$3) -> 0 | AM9: =countif(B9:AG9,$AM$3) -> 14 | AN9: =countif(B9:AG9,AN$3) -> 0 | AO9: =(countif(B9:AL9,"A")) -> 0 | AP9: =countif(B9:AO9,AP$3) -> 0 | AQ9: =countif(B9:AP9,AQ$3) -> 0 | AR9: 100 | AS9: =SUMIFs('Spiffs & Deductions'!B$3:B1005,'Spiffs & Deductions'!A$3:A1005,A9,'Spiffs & Deductions'!C$3:C1005,$AS$3) -> 0 | AT9: =SUMIF('Spiffs & Deductions'!H$4:H1005,A9,'Spiffs & Deductions'!I$4:I1005) -> 0
A10: =Workforce!A8 -> Caroline Richards | AH10: =(countif(B10:AG10,AH$3))+AI10+AJ10+(AL10*0.5)+(AK10*0.75) -> 0 | AI10: =countif(B10:AG10,$AI$3) -> 0 | AJ10: =countif(B10:AG10,AJ$3) -> 0 | AK10: =countif(B10:AG10,AK$3) -> 0 | AL10: =countif(B10:AG10,AL$3) -> 0 | AM10: =countif(B10:AG10,$AM$3) -> 0 | AN10: =countif(B10:AG10,AN$3) -> 0 | AO10: =(countif(B10:AL10,"A")) -> 0 | AP10: =countif(B10:AO10,AP$3) -> 0 | AQ10: =countif(B10:AP10,AQ$3) -> 0 | AR10: =SUMIF('Spiffs & Deductions'!A$3:A1005,A10,'Spiffs & Deductions'!B$3:B1005) -> 0 | AS10: =SUMIFs('Spiffs & Deductions'!B$3:B1005,'Spiffs & Deductions'!A$3:A1005,A10,'Spiffs & Deductions'!C$3:C1005,$AS$3) -> 0 | AT10: =SUMIF('Spiffs & Deductions'!H$4:H1005,A10,'Spiffs & Deductions'!I$4:I1005) -> 0
A11: Month | B11: =iferror(concatenate(" Enter ", 'Attendance key'!$B$6, " for ",'Attendance key'!$C$6, ", ", 'Attendance key'!$B$7, " for ", 'Attendance key'!$C$7, ", ", 'Attendance key'!$B$8, " for ", 'Attendance key'!$C$8, ", and ", 'Attendance key'!$B$9, " for ", 'Attendance key'!$C$9, ". Use the 'Attendance key' tab to customize. "),"") | AH11: =(countif(B11:AG11,AH$3))+AI11+AJ11+(AL11*0.5)+(AK11*0.75) -> 0 | AI11: =countif(B11:AG11,$AI$3) -> 0 | AJ11: =countif(B11:AG11,AJ$3) -> 0 | AK11: =countif(B11:AG11,AK$3) -> 0 | AL11: =countif(B11:AG11,AL$3) -> 0 | AM11: =countif(B11:AG11,$AM$3) -> 0 | AN11: =countif(B11:AG11,AN$3) -> 0 | AO11: =(countif(B11:AL11,"A")) -> 0 | AP11: =countif(B11:AO11,AP$3) -> 0 | AQ11: =countif(B11:AP11,AQ$3) -> 0 | AR11: =SUMIF('Spiffs & Deductions'!A$3:A1005,A11,'Spiffs & Deductions'!B$3:B1005) -> 0 | AS11: =SUMIFs('Spiffs & Deductions'!B$3:B1005,'Spiffs & Deductions'!A$3:A1005,A11,'Spiffs & Deductions'!C$3:C1005,$AS$3) -> 0 | AT11: =SUMIF('Spiffs & Deductions'!H$4:H1005,A11,'Spiffs & Deductions'!I$4:I1005) -> 0
A12: Date | B12: 46050 | C12: =B12+1 -> 46051 | D12: =C12+1 -> 46052 | E12: =D12+1 -> 46053 | F12: =E12+1 -> 46054 | G12: =F12+1 -> 46055 | H12: =G12+1 -> 46056 | I12: =H12+1 -> 46057 | J12: =I12+1 -> 46058 | ... AF12: =AE12+1 -> 46080 | AH12: Present | AI12: Late | AK12: Off | AN12: Double paid | AO12: Absent | AP12: N.S.N.C. | AQ12: Training | AR12: Spiffs | AT12: Deductions
A13: Day | B13: =B12 -> 46050 | C13: =C12 -> 46051 | D13: =D12 -> 46052 | E13: =E12 -> 46053 | F13: =F12 -> 46054 | G13: =G12 -> 46055 | H13: =H12 -> 46056 | I13: =I12 -> 46057 | ... AF13: =AF12 -> 46080 | AH13: P | AI13: L1 | AJ13: L2 | AK13: Q | AL13: H | AM13: Off | AN13: D | AO13: A | AP13: N | AQ13: T | AR13: All | AS13: Paid
A14: Ben Arthur | B14: P | C14: P | D14: P | E14: Off | F14: Off | G14: P | H14: P | I14: P | J14: P | K14: P | L14: Off | M14: Off | N14: P | O14: P | P14: A | Q14: P | R14: P | S14: Off | T14: Off | U14: P | V14: L1 | W14: P | X14: Off | Y14: P | Z14: Off | AA14: Off | AB14: A | AC14: P | AD14: P | AE14: P | AF14: P | AH14: =(countif(B14:AG14,AH$3))+AI14+AJ14+(AL14*0.5)+(AK14*0.75) -> 20 | AI14: =countif(B14:AG14,$AI$3) -> 1 | AJ14: =countif(B14:AG14,AJ$3) -> 0 | AK14: =countif(B14:AG14,AK$3) -> 0 | AL14: =countif(B14:AG14,AL$3) -> 0 | AM14: =countif(B14:AG14,$AM$3) -> 9 | AN14: =countif(B14:AG14,AN$3) -> 0 | AO14: =(countif(B14:AL14,"A")) -> 2 | AP14: =countif(B14:AO14,AP$3) -> 0 | AQ14: =countif(B14:AP14,AQ$3) -> 0 | AR14: =SUMIF('Spiffs & Deductions'!A$3:A1005,A14,'Spiffs & Deductions'!B$3:B1005) -> 0 | AS14: =SUMIFs('Spiffs & Deductions'!B$3:B1005,'Spiffs & Deductions'!A$3:A1005,A14,'Spiffs & Deductions'!C$3:C1005,$AS$3) -> 0 | AT14: =SUMIF('Spiffs & Deductions'!H$4:H1005,A14,'Spiffs & Deductions'!I$4:I1005) -> 0
A15: Jimmy Pearson | B15: P | C15: P | D15: P | E15: Off | F15: Off | G15: P | H15: P | I15: P | J15: P | K15: P | L15: Off | M15: Off | N15: P | O15: P | P15: P | Q15: P | R15: P | S15: Off | T15: Off | U15: P | V15: P | W15: P | X15: Off | Y15: P | Z15: Off | AA15: Off | AB15: P | AC15: P | AD15: P | AE15: L2 | AF15: P | AH15: =(countif(B15:AG15,AH$3))+AI15+AJ15+(AL15*0.5)+(AK15*0.75) -> 22 | AI15: =countif(B15:AG15,$AI$3) -> 0 | AJ15: =countif(B15:AG15,AJ$3) -> 1 | AK15: =countif(B15:AG15,AK$3) -> 0 | AL15: =countif(B15:AG15,AL$3) -> 0 | AM15: =countif(B15:AG15,$AM$3) -> 9 | AN15: =countif(B15:AG15,AN$3) -> 0 | AO15: =(countif(B15:AL15,"A")) -> 0 | AP15: =countif(B15:AO15,AP$3) -> 0 | AQ15: =countif(B15:AP15,AQ$3) -> 0 | AR15: =SUMIF('Spiffs & Deductions'!A$3:A1005,A15,'Spiffs & Deductions'!B$3:B1005) -> 0 | AS15: =SUMIFs('Spiffs & Deductions'!B$3:B1005,'Spiffs & Deductions'!A$3:A1005,A15,'Spiffs & Deductions'!C$3:C1005,$AS$3) -> 0 | AT15: =SUMIF('Spiffs & Deductions'!H$4:H1005,A15,'Spiffs & Deductions'!I$4:I1005) -> 0
A16: Kaity James | B16: P | C16: P | D16: P | E16: Off | F16: Off | G16: P | H16: P | I16: P | J16: P | K16: P | L16: Off | M16: Off | N16: P | O16: P | P16: P | Q16: P | R16: P | S16: Off | T16: Off | U16: A | V16: A | W16: P | X16: Off | Y16: P | Z16: Off | AA16: Off | AB16: P | AC16: P | AD16: P | AE16: P | AF16: P | AH16: =(countif(B16:AG16,AH$3))+AI16+AJ16+(AL16*0.5)+(AK16*0.75) -> 20 | AI16: =countif(B16:AG16,$AI$3) -> 0 | AJ16: =countif(B16:AG16,AJ$3) -> 0 | AK16: =countif(B16:AG16,AK$3) -> 0 | AL16: =countif(B16:AG16,AL$3) -> 0 | AM16: =countif(B16:AG16,$AM$3) -> 9 | AN16: =countif(B16:AG16,AN$3) -> 0 | AO16: =(countif(B16:AL16,"A")) -> 2 | AP16: =countif(B16:AO16,AP$3) -> 0 | AQ16: =countif(B16:AP16,AQ$3) -> 0 | AR16: =SUMIF('Spiffs & Deductions'!A$3:A1005,A16,'Spiffs & Deductions'!B$3:B1005) -> 0 | AS16: =SUMIFs('Spiffs & Deductions'!B$3:B1005,'Spiffs & Deductions'!A$3:A1005,A16,'Spiffs & Deductions'!C$3:C1005,$AS$3) -> 0 | AT16: =SUMIF('Spiffs & Deductions'!H$4:H1005,A16,'Spiffs & Deductions'!I$4:I1005) -> 0
A17: Selene Myles | B17: P | C17: P | D17: P | E17: Off | F17: Off | G17: P | H17: P | I17: P | J17: P | K17: P | L17: Off | M17: Off | N17: P | O17: P | P17: P | Q17: P | R17: P | S17: Off | T17: Off | U17: A | V17: A | W17: P | X17: Off | Y17: P | Z17: Off | AA17: Off | AB17: P | AC17: P | AD17: P | AE17: P | AF17: P | AH17: =(countif(B17:AG17,AH$3))+AI17+AJ17+(AL17*0.5)+(AK17*0.75) -> 20 | AI17: =countif(B17:AG17,$AI$3) -> 0 | AJ17: =countif(B17:AG17,AJ$3) -> 0 | AK17: =countif(B17:AG17,AK$3) -> 0 | AL17: =countif(B17:AG17,AL$3) -> 0 | AM17: =countif(B17:AG17,$AM$3) -> 9 | AN17: =countif(B17:AG17,AN$3) -> 0 | AO17: =(countif(B17:AL17,"A")) -> 2 | AP17: =countif(B17:AO17,AP$3) -> 0 | AQ17: =countif(B17:AP17,AQ$3) -> 0 | AR17: =SUMIF('Spiffs & Deductions'!A$3:A1005,A17,'Spiffs & Deductions'!B$3:B1005) -> 0 | AS17: =SUMIFs('Spiffs & Deductions'!B$3:B1005,'Spiffs & Deductions'!A$3:A1005,A17,'Spiffs & Deductions'!C$3:C1005,$AS$3) -> 0 | AT17: =SUMIF('Spiffs & Deductions'!H$4:H1005,A17,'Spiffs & Deductions'!I$4:I1005) -> 0
A18: Mohamed | B18: P | C18: P | D18: P | E18: Off | F18: Off | G18: P | H18: P | I18: P | J18: P | K18: P | L18: Off | M18: Off | N18: P | O18: P | P18: P | Q18: P | R18: P | S18: Off | T18: Off | U18: P | V18: P | W18: P | X18: P | Y18: P | Z18: Off | AA18: Off | AB18: P | AC18: P | AD18: P | AE18: P | AF18: P | AH18: =(countif(B18:AG18,AH$3))+AI18+AJ18+(AL18*0.5)+(AK18*0.75) -> 23 | AI18: =countif(B18:AG18,$AI$3) -> 0 | AJ18: =countif(B18:AG18,AJ$3) -> 0 | AK18: =countif(B18:AG18,AK$3) -> 0 | AL18: =countif(B18:AG18,AL$3) -> 0 | AM18: =countif(B18:AG18,$AM$3) -> 8 | AN18: =countif(B18:AG18,AN$3) -> 0 | AO18: =(countif(B18:AL18,"A")) -> 0 | AP18: =countif(B18:AO18,AP$3) -> 0 | AQ18: =countif(B18:AP18,AQ$3) -> 0 | AR18: =SUMIF('Spiffs & Deductions'!A$3:A1005,A18,'Spiffs & Deductions'!B$3:B1005) -> 0 | AS18: =SUMIFs('Spiffs & Deductions'!B$3:B1005,'Spiffs & Deductions'!A$3:A1005,A18,'Spiffs & Deductions'!C$3:C1005,$AS$3) -> 0 | AT18: =SUMIF('Spiffs & Deductions'!H$4:H1005,A18,'Spiffs & Deductions'!I$4:I1005) -> 0
A19: Malak El Khateeb | B19: P | C19: P | D19: P | E19: Off | F19: Off | G19: P | H19: P | I19: P | J19: P | K19: P | L19: Off | M19: Off | N19: - | O19: - | P19: - | Q19: - | R19: - | S19: Off | T19: Off | U19: - | V19: - | W19: - | X19: - | Y19: - | Z19: Off | AA19: Off | AB19: - | AC19: - | AD19: - | AE19: - | AF19: - | AH19: =(countif(B19:AG19,AH$3))+AI19+AJ19+(AL19*0.5)+(AK19*0.75) -> 8 | AI19: =countif(B19:AG19,$AI$3) -> 0 | AJ19: =countif(B19:AG19,AJ$3) -> 0 | AK19: =countif(B19:AG19,AK$3) -> 0 | AL19: =countif(B19:AG19,AL$3) -> 0 | AM19: =countif(B19:AG19,$AM$3) -> 8 | AN19: =countif(B19:AG19,AN$3) -> 0 | AO19: =(countif(B19:AL19,"A")) -> 0 | AP19: =countif(B19:AO19,AP$3) -> 0 | AQ19: =countif(B19:AP19,AQ$3) -> 0 | AR19: =SUMIF('Spiffs & Deductions'!A$3:A1005,A19,'Spiffs & Deductions'!B$3:B1005) -> 0 | AS19: =SUMIFs('Spiffs & Deductions'!B$3:B1005,'Spiffs & Deductions'!A$3:A1005,A19,'Spiffs & Deductions'!C$3:C1005,$AS$3) -> 0 | AT19: =SUMIF('Spiffs & Deductions'!H$4:H1005,A19,'Spiffs & Deductions'!I$4:I1005) -> 0
A20: Youseef (New comer) | B20: - | C20: - | D20: - | E20: - | F20: - | G20: - | H20: - | I20: - | J20: - | K20: - | L20: - | M20: - | N20: - | O20: - | P20: - | Q20: - | R20: - | S20: - | T20: - | U20: T | V20: P | W20: P | X20: P | Y20: P | Z20: Off | AA20: Off | AB20: - | AC20: - | AD20: - | AE20: - | AF20: - | AH20: =(countif(B20:AG20,AH$3))+AI20+AJ20+(AL20*0.5)+(AK20*0.75) -> 4 | AI20: =countif(B20:AG20,$AI$3) -> 0 | AJ20: =countif(B20:AG20,AJ$3) -> 0 | AK20: =countif(B20:AG20,AK$3) -> 0 | AL20: =countif(B20:AG20,AL$3) -> 0 | AM20: =countif(B20:AG20,$AM$3) -> 2 | AN20: =countif(B20:AG20,AN$3) -> 0 | AO20: =(countif(B20:AL20,"A")) -> 0 | AP20: =countif(B20:AO20,AP$3) -> 0 | AQ20: =countif(B20:AP20,AQ$3) -> 1 | AR20: =SUMIF('Spiffs & Deductions'!A$3:A1005,A20,'Spiffs & Deductions'!B$3:B1005) -> 0 | AS20: =SUMIFs('Spiffs & Deductions'!B$3:B1005,'Spiffs & Deductions'!A$3:A1005,A20,'Spiffs & Deductions'!C$3:C1005,$AS$3) -> 0 | AT20: =SUMIF('Spiffs & Deductions'!H$4:H1005,A20,'Spiffs & Deductions'!I$4:I1005) -> 0
A22: Month
A23: Date | B23: 46081 | C23: 46082 | D23: 46083 | E23: 46084 | F23: 46085 | G23: 46086 | H23: 46087 | I23: 46088 | J23: 46089 | K23: 46090 | L23: 46091 | M23: 46092 | N23: 46093 | O23: 46094 | P23: 46095 | Q23: 46096 | R23: 46097 | S23: 46098 | T23: 46099 | U23: 46100 | V23: 46101 | W23: 46102 | X23: 46103 | Y23: 46104 | Z23: 46105 | AA23: 46106 | AB23: 46107 | AC23: 46108 | AH23: Present | AI23: Late | AK23: Off | AN23: Double paid | AO23: Absent | AP23: N.S.N.C. | AQ23: Training | AR23: Spiffs | AT23: Deductions
A24: Day | B24: =B23 -> 46081 | C24: =C23 -> 46082 | D24: =D23 -> 46083 | E24: =E23 -> 46084 | F24: =F23 -> 46085 | G24: =G23 -> 46086 | H24: =H23 -> 46087 | I24: =I23 -> 46088 | ... AC24: =AC23 -> 46108 | AH24: P | AI24: L1 | AJ24: L2 | AK24: Q | AL24: H | AM24: Off | AN24: D | AO24: A | AP24: N | AQ24: T | AR24: All | AS24: Paid
A25: Ben Arthur | B25: Off | C25: Off | D25: L2 | E25: P | F25: P | G25: P | H25: P | I25: Off | J25: Off | K25: P | L25: L1 | M25: P | N25: P | O25: P | P25: Off | Q25: Off | R25: P | S25: L1 | T25: A | U25: P | V25: Off | W25: Off | X25: Off | Y25: P | Z25: P | AA25: P | AB25: P | AC25: P | AH25: =(countif(B25:AG25,AH$3))+AI25+AJ25+(AL25*0.5)+(AK25*0.75) -> 18 | AI25: =countif(B25:AG25,$AI$3) -> 2 | AJ25: =countif(B25:AG25,AJ$3) -> 1 | AK25: =countif(B25:AG25,AK$3) -> 0 | AL25: =countif(B25:AG25,AL$3) -> 0 | AM25: =countif(B25:AG25,$AM$3) -> 9 | AN25: =countif(B25:AG25,AN$3) -> 0 | AO25: =(countif(B25:AL25,"A")) -> 1 | AP25: =countif(B25:AO25,AP$3) -> 0 | AQ25: =countif(B25:AP25,AQ$3) -> 0 | AR25: =SUMIF('Spiffs & Deductions'!A$3:A1005,A25,'Spiffs & Deductions'!B$3:B1005) -> 0 | AS25: =SUMIFs('Spiffs & Deductions'!B$3:B1005,'Spiffs & Deductions'!A$3:A1005,A25,'Spiffs & Deductions'!C$3:C1005,$AS$3) -> 0 | AT25: =SUMIF('Spiffs & Deductions'!H$4:H1005,A25,'Spiffs & Deductions'!I$4:I1005) -> 0
A26: Jimmy Pearson | B26: Off | C26: Off | D26: P | E26: P | F26: P | G26: P | H26: A | I26: Off | J26: Off | K26: P | L26: P | M26: P | N26: P | O26: P | P26: Off | Q26: Off | R26: P | S26: L2 | T26: P | U26: P | V26: Off | W26: Off | X26: Off | Y26: L1 | Z26: P | AA26: L2 | AB26: P | AC26: P | AH26: =(countif(B26:AG26,AH$3))+AI26+AJ26+(AL26*0.5)+(AK26*0.75) -> 18 | AI26: =countif(B26:AG26,$AI$3) -> 1 | AJ26: =countif(B26:AG26,AJ$3) -> 2 | AK26: =countif(B26:AG26,AK$3) -> 0 | AL26: =countif(B26:AG26,AL$3) -> 0 | AM26: =countif(B26:AG26,$AM$3) -> 9 | AN26: =countif(B26:AG26,AN$3) -> 0 | AO26: =(countif(B26:AL26,"A")) -> 1 | AP26: =countif(B26:AO26,AP$3) -> 0 | AQ26: =countif(B26:AP26,AQ$3) -> 0 | AR26: =SUMIF('Spiffs & Deductions'!A$3:A1005,A26,'Spiffs & Deductions'!B$3:B1005) -> 0 | AS26: =SUMIFs('Spiffs & Deductions'!B$3:B1005,'Spiffs & Deductions'!A$3:A1005,A26,'Spiffs & Deductions'!C$3:C1005,$AS$3) -> 0 | AT26: =SUMIF('Spiffs & Deductions'!H$4:H1005,A26,'Spiffs & Deductions'!I$4:I1005) -> 0
A27: Kaity James | B27: Off | C27: Off | D27: P | E27: P | F27: P | G27: P | H27: P | I27: Off | J27: Off | K27: P | L27: P | M27: P | N27: P | O27: H | P27: Off | Q27: Off | R27: P | S27: P | T27: P | U27: P | V27: Off | W27: Off | X27: Off | Y27: P | Z27: P | AA27: A | AB27: P | AC27: P | AH27: =(countif(B27:AG27,AH$3))+AI27+AJ27+(AL27*0.5)+(AK27*0.75) -> 17.5 | AI27: =countif(B27:AG27,$AI$3) -> 0 | AJ27: =countif(B27:AG27,AJ$3) -> 0 | AK27: =countif(B27:AG27,AK$3) -> 0 | AL27: =countif(B27:AG27,AL$3) -> 1 | AM27: =countif(B27:AG27,$AM$3) -> 9 | AN27: =countif(B27:AG27,AN$3) -> 0 | AO27: =(countif(B27:AL27,"A")) -> 1 | AP27: =countif(B27:AO27,AP$3) -> 0 | AQ27: =countif(B27:AP27,AQ$3) -> 0 | AR27: =SUMIF('Spiffs & Deductions'!A$3:A1005,A27,'Spiffs & Deductions'!B$3:B1005) -> 0 | AS27: =SUMIFs('Spiffs & Deductions'!B$3:B1005,'Spiffs & Deductions'!A$3:A1005,A27,'Spiffs & Deductions'!C$3:C1005,$AS$3) -> 0 | AT27: =SUMIF('Spiffs & Deductions'!H$4:H1005,A27,'Spiffs & Deductions'!I$4:I1005) -> 0
A28: Selene Myles | B28: Off | C28: Off | D28: P | E28: P | F28: P | G28: P | H28: P | I28: Off | J28: Off | K28: P | L28: P | M28: P | N28: P | O28: H | P28: Off | Q28: Off | R28: P | S28: P | T28: P | U28: P | V28: Off | W28: Off | X28: Off | Y28: P | Z28: P | AA28: A | AB28: A | AC28: P | AH28: =(countif(B28:AG28,AH$3))+AI28+AJ28+(AL28*0.5)+(AK28*0.75) -> 16.5 | AI28: =countif(B28:AG28,$AI$3) -> 0 | AJ28: =countif(B28:AG28,AJ$3) -> 0 | AK28: =countif(B28:AG28,AK$3) -> 0 | AL28: =countif(B28:AG28,AL$3) -> 1 | AM28: =countif(B28:AG28,$AM$3) -> 9 | AN28: =countif(B28:AG28,AN$3) -> 0 | AO28: =(countif(B28:AL28,"A")) -> 2 | AP28: =countif(B28:AO28,AP$3) -> 0 | AQ28: =countif(B28:AP28,AQ$3) -> 0 | AR28: =SUMIF('Spiffs & Deductions'!A$3:A1005,A28,'Spiffs & Deductions'!B$3:B1005) -> 0 | AS28: =SUMIFs('Spiffs & Deductions'!B$3:B1005,'Spiffs & Deductions'!A$3:A1005,A28,'Spiffs & Deductions'!C$3:C1005,$AS$3) -> 0 | AT28: =SUMIF('Spiffs & Deductions'!H$4:H1005,A28,'Spiffs & Deductions'!I$4:I1005) -> 0
A29: Mohamed | B29: Off | C29: Off | I29: Off | J29: Off | P29: Off | Q29: Off | W29: Off | X29: Off | AH29: =(countif(B29:AG29,AH$3))+AI29+AJ29+(AL29*0.5)+(AK29*0.75) -> 0 | AI29: =countif(B29:AG29,$AI$3) -> 0 | AJ29: =countif(B29:AG29,AJ$3) -> 0 | AK29: =countif(B29:AG29,AK$3) -> 0 | AL29: =countif(B29:AG29,AL$3) -> 0 | AM29: =countif(B29:AG29,$AM$3) -> 8 | AN29: =countif(B29:AG29,AN$3) -> 0 | AO29: =(countif(B29:AL29,"A")) -> 0 | AP29: =countif(B29:AO29,AP$3) -> 0 | AQ29: =countif(B29:AP29,AQ$3) -> 0 | AR29: =SUMIF('Spiffs & Deductions'!A$3:A1005,A29,'Spiffs & Deductions'!B$3:B1005) -> 0 | AS29: =SUMIFs('Spiffs & Deductions'!B$3:B1005,'Spiffs & Deductions'!A$3:A1005,A29,'Spiffs & Deductions'!C$3:C1005,$AS$3) -> 0 | AT29: =SUMIF('Spiffs & Deductions'!H$4:H1005,A29,'Spiffs & Deductions'!I$4:I1005) -> 0
A30: Malak El Khateeb | B30: Off | C30: Off | I30: Off | J30: Off | P30: Off | Q30: Off | W30: Off | X30: Off | AH30: =(countif(B30:AG30,AH$3))+AI30+AJ30+(AL30*0.5)+(AK30*0.75) -> 0 | AI30: =countif(B30:AG30,$AI$3) -> 0 | AJ30: =countif(B30:AG30,AJ$3) -> 0 | AK30: =countif(B30:AG30,AK$3) -> 0 | AL30: =countif(B30:AG30,AL$3) -> 0 | AM30: =countif(B30:AG30,$AM$3) -> 8 | AN30: =countif(B30:AG30,AN$3) -> 0 | AO30: =(countif(B30:AL30,"A")) -> 0 | AP30: =countif(B30:AO30,AP$3) -> 0 | AQ30: =countif(B30:AP30,AQ$3) -> 0 | AR30: =SUMIF('Spiffs & Deductions'!A$3:A1005,A30,'Spiffs & Deductions'!B$3:B1005) -> 0 | AS30: =SUMIFs('Spiffs & Deductions'!B$3:B1005,'Spiffs & Deductions'!A$3:A1005,A30,'Spiffs & Deductions'!C$3:C1005,$AS$3) -> 0 | AT30: =SUMIF('Spiffs & Deductions'!H$4:H1005,A30,'Spiffs & Deductions'!I$4:I1005) -> 0
A31: Youseef (New comer) | B31: Off | C31: Off | I31: Off | J31: Off | P31: Off | Q31: Off | W31: Off | X31: Off | AH31: =(countif(B31:AG31,AH$3))+AI31+AJ31+(AL31*0.5)+(AK31*0.75) -> 0 | AI31: =countif(B31:AG31,$AI$3) -> 0 | AJ31: =countif(B31:AG31,AJ$3) -> 0 | AK31: =countif(B31:AG31,AK$3) -> 0 | AL31: =countif(B31:AG31,AL$3) -> 0 | AM31: =countif(B31:AG31,$AM$3) -> 8 | AN31: =countif(B31:AG31,AN$3) -> 0 | AO31: =(countif(B31:AL31,"A")) -> 0 | AP31: =countif(B31:AO31,AP$3) -> 0 | AQ31: =countif(B31:AP31,AQ$3) -> 0 | AR31: =SUMIF('Spiffs & Deductions'!A$3:A1005,A31,'Spiffs & Deductions'!B$3:B1005) -> 0 | AS31: =SUMIFs('Spiffs & Deductions'!B$3:B1005,'Spiffs & Deductions'!A$3:A1005,A31,'Spiffs & Deductions'!C$3:C1005,$AS$3) -> 0 | AT31: =SUMIF('Spiffs & Deductions'!H$4:H1005,A31,'Spiffs & Deductions'!I$4:I1005) -> 0
A33: Month
A34: Date | B34: 46109 | C34: 46110 | D34: 46111 | E34: 46112 | F34: 46113 | G34: 46114 | H34: 46115 | I34: 46116 | J34: 46117 | K34: 46118 | L34: 46119 | M34: 46120 | N34: 46121 | O34: 46122 | P34: 46123 | Q34: 46124 | R34: 46125 | S34: 46126 | T34: 46127 | U34: 46128 | V34: 46129 | W34: 46130 | X34: 46131 | Y34: 46132 | Z34: 46133 | AA34: 46134 | AB34: 46135 | AC34: 46136 | AD34: 46137 | AE34: 46138 | AF34: 46139 | AH34: Present | AI34: Late | AK34: Off | AN34: Double paid | AO34: Absent | AP34: N.S.N.C. | AQ34: Training | AR34: Spiffs | AT34: Deductions
A35: Day | B35: =B34 -> 46109 | C35: =C34 -> 46110 | D35: =D34 -> 46111 | E35: =E34 -> 46112 | F35: =F34 -> 46113 | G35: =G34 -> 46114 | H35: =H34 -> 46115 | I35: =I34 -> 46116 | ... AF35: =AF34 -> 46139 | AH35: P | AI35: L1 | AJ35: L2 | AK35: Q | AL35: H | AM35: Off | AN35: D | AO35: A | AP35: N | AQ35: T | AR35: All | AS35: Paid
A36: Ben Arthur | B36: Off | C36: Off | D36: P | E36: H | F36: P | G36: Q | H36: P | I36: Off | J36: Off | K36: P | L36: P | M36: P | N36: H | O36: P | P36: Off | Q36: Off | R36: P | S36: P | T36: P | U36: P | V36: P | W36: Off | X36: Off | Y36: P | Z36: P | AA36: P | AB36: H | AC36: P | AD36: Off | AE36: Off | AF36: L2 | AH36: =(countif(B36:AG36,AH$3))+AI36+AJ36+(AL36*0.5)+(AK36*0.75) -> 19.25 | AI36: =countif(B36:AG36,$AI$3) -> 0 | AJ36: =countif(B36:AG36,AJ$3) -> 1 | AK36: =countif(B36:AG36,AK$3) -> 1 | AL36: =countif(B36:AG36,AL$3) -> 3 | AM36: =countif(B36:AG36,$AM$3) -> 10 | AN36: =countif(B36:AG36,AN$3) -> 0 | AO36: =(countif(B36:AL36,"A")) -> 0 | AP36: =countif(B36:AO36,AP$3) -> 0 | AQ36: =countif(B36:AP36,AQ$3) -> 0 | AR36: =SUMIF('Spiffs & Deductions'!A$3:A1005,A36,'Spiffs & Deductions'!B$3:B1005) -> 0 | AS36: =SUMIFs('Spiffs & Deductions'!B$3:B1005,'Spiffs & Deductions'!A$3:A1005,A36,'Spiffs & Deductions'!C$3:C1005,$AS$3) -> 0 | AT36: =SUMIF('Spiffs & Deductions'!H$4:H1005,A36,'Spiffs & Deductions'!I$4:I1005) -> 0
A37: Jimmy Pearson | B37: Off | C37: Off | D37: P | E37: P | F37: P | G37: L2 | H37: P | I37: Off | J37: Off | K37: P | L37: P | M37: L2 | N37: P | O37: P | P37: Off | Q37: Off | R37: P | S37: P | T37: P | U37: P | V37: L1 | W37: Off | X37: Off | Y37: P | Z37: P | AA37: P | AB37: L1 | AC37: P | AD37: Off | AE37: Off | AF37: P | AH37: =(countif(B37:AG37,AH$3))+AI37+AJ37+(AL37*0.5)+(AK37*0.75) -> 21 | AI37: =countif(B37:AG37,$AI$3) -> 2 | AJ37: =countif(B37:AG37,AJ$3) -> 2 | AK37: =countif(B37:AG37,AK$3) -> 0 | AL37: =countif(B37:AG37,AL$3) -> 0 | AM37: =countif(B37:AG37,$AM$3) -> 10 | AN37: =countif(B37:AG37,AN$3) -> 0 | AO37: =(countif(B37:AL37,"A")) -> 0 | AP37: =countif(B37:AO37,AP$3) -> 0 | AQ37: =countif(B37:AP37,AQ$3) -> 0 | AR37: =SUMIF('Spiffs & Deductions'!A$3:A1005,A37,'Spiffs & Deductions'!B$3:B1005) -> 0 | AS37: =SUMIFs('Spiffs & Deductions'!B$3:B1005,'Spiffs & Deductions'!A$3:A1005,A37,'Spiffs & Deductions'!C$3:C1005,$AS$3) -> 0 | AT37: =SUMIF('Spiffs & Deductions'!H$4:H1005,A37,'Spiffs & Deductions'!I$4:I1005) -> 0
A38: Kaity James | B38: Off | C38: Off | D38: L2 | E38: A | F38: P | G38: P | H38: P | I38: Off | J38: Off | K38: P | L38: P | M38: P | N38: P | O38: P | P38: Off | Q38: Off | R38: P | S38: P | T38: L2 | U38: P | V38: P | W38: Off | X38: Off | Y38: H | Z38: P | AA38: P | AB38: P | AC38: H | AD38: Off | AE38: Off | AF38: P | AH38: =(countif(B38:AG38,AH$3))+AI38+AJ38+(AL38*0.5)+(AK38*0.75) -> 19 | AI38: =countif(B38:AG38,$AI$3) -> 0 | AJ38: =countif(B38:AG38,AJ$3) -> 2 | AK38: =countif(B38:AG38,AK$3) -> 0 | AL38: =countif(B38:AG38,AL$3) -> 2 | AM38: =countif(B38:AG38,$AM$3) -> 10 | AN38: =countif(B38:AG38,AN$3) -> 0 | AO38: =(countif(B38:AL38,"A")) -> 1 | AP38: =countif(B38:AO38,AP$3) -> 0 | AQ38: =countif(B38:AP38,AQ$3) -> 0 | AR38: =SUMIF('Spiffs & Deductions'!A$3:A1005,A38,'Spiffs & Deductions'!B$3:B1005) -> 0 | AS38: =SUMIFs('Spiffs & Deductions'!B$3:B1005,'Spiffs & Deductions'!A$3:A1005,A38,'Spiffs & Deductions'!C$3:C1005,$AS$3) -> 0 | AT38: =SUMIF('Spiffs & Deductions'!H$4:H1005,A38,'Spiffs & Deductions'!I$4:I1005) -> 0
A39: Selene Myles | B39: Off | C39: Off | D39: H | E39: A | F39: A | G39: P | H39: P | I39: Off | J39: Off | K39: P | L39: P | M39: P | N39: P | O39: P | P39: Off | Q39: Off | R39: P | S39: P | T39: P | U39: P | V39: P | W39: Off | X39: Off | Y39: A | Z39: P | AA39: P | AB39: P | AC39: P | AD39: Off | AE39: Off | AF39: P | AH39: =(countif(B39:AG39,AH$3))+AI39+AJ39+(AL39*0.5)+(AK39*0.75) -> 17.5 | AI39: =countif(B39:AG39,$AI$3) -> 0 | AJ39: =countif(B39:AG39,AJ$3) -> 0 | AK39: =countif(B39:AG39,AK$3) -> 0 | AL39: =countif(B39:AG39,AL$3) -> 1 | AM39: =countif(B39:AG39,$AM$3) -> 10 | AN39: =countif(B39:AG39,AN$3) -> 0 | AO39: =(countif(B39:AL39,"A")) -> 3 | AP39: =countif(B39:AO39,AP$3) -> 0 | AQ39: =countif(B39:AP39,AQ$3) -> 0 | AR39: =SUMIF('Spiffs & Deductions'!A$3:A1005,A39,'Spiffs & Deductions'!B$3:B1005) -> 0 | AS39: =SUMIFs('Spiffs & Deductions'!B$3:B1005,'Spiffs & Deductions'!A$3:A1005,A39,'Spiffs & Deductions'!C$3:C1005,$AS$3) -> 0 | AT39: =SUMIF('Spiffs & Deductions'!H$4:H1005,A39,'Spiffs & Deductions'!I$4:I1005) -> 0
A41: Month
A42: Date | B42: 46140 | C42: 46141 | D42: 46142 | E42: 46143 | F42: 46144 | G42: 46145 | H42: 46146 | I42: 46147 | J42: 46148 | K42: 46149 | L42: 46150 | M42: 46151 | N42: 46152 | O42: 46153 | P42: 46154 | Q42: 46155 | R42: 46156 | S42: 46157 | T42: 46158 | U42: 46159 | V42: 46160 | W42: 46161 | X42: 46162 | Y42: 46163 | Z42: 46164 | AA42: 46165 | AB42: 46166 | AC42: 46167 | AD42: 46168 | AE42: 46169 | AF42: 46170 | AH42: Present | AI42: Late | AK42: Off | AN42: Double paid | AO42: Absent | AP42: N.S.N.C. | AQ42: Training | AR42: Spiffs | AT42: Deductions
A43: Day | B43: =B42 -> 46140 | C43: =C42 -> 46141 | D43: =D42 -> 46142 | E43: =E42 -> 46143 | F43: =F42 -> 46144 | G43: =G42 -> 46145 | H43: =H42 -> 46146 | I43: =I42 -> 46147 | ... AF43: =AF42 -> 46170 | AH43: P | AI43: L1 | AJ43: L2 | AK43: Q | AL43: H | AM43: Off | AN43: D | AO43: A | AP43: N | AQ43: T | AR43: All | AS43: Paid
...

Sheet Key
A1: ATTENDANCE KEY
A2: P | B2: Present
A3: L1 | B3: Late (Deduction 25)
A4: L2 | B4: Late (Deduction 50)
A5: Q | B5: Quarter day deduction (3/4 day Present)
A6: H | B6: Half day
A7: A | B7: Excused Absence
A8: N | B8: No Show No call (unexcused absence)
A9: D | B9: Double paid
A10: T | B10: Training
A11: - | B11: Unemployed (before/after employment)
A12: Off | B12: Off (week-ends/holidays)

Sheet Spiffs & Deductions
A1: Spiffs | H1: Deductions
A2: Agent Name | B2: Amount | C2: Paid / Unpaid | D2: Description | E2: Date | H2: Agent Name | I2: Amount | J2: Description | K2: Date
A17: =Workforce!A15
A18: =Workforce!A16
A19: =Workforce!A17
A20: =Workforce!A18
