Workbook

Sheet New Meetings
A1: SUB | B1: Opener | C1: Status | D1: Date Added | E1: Company Name | F1: Authorized Person | G1: Phone | H1: EMAIL | I1: Meeting Time | J1: Opener Summary | K1: George's Notes | L1: Auto Scheduler | M1: Last Call | N1: Action | O1: Checkbox | P1: Log | Q1: NPI
A2: ORT+CGM+LYMPH W | B2: Jasmine | D2: 46197 | E2: DENISE V. LYONS MEDICAL SUPPLY HOUSE | F2: DENISE V. LYONS | G2: 303-257-1938 | H2: denisevlyons@outlook.com | I2: Mon 10:30 | J2: ort cgm lymphedema / medicaid aetna humana united healthcare CO based | Q2: 1366915209
A3: IMMUNE | B3: Jane | C3: Follow Up | D3: 46092 | E3: SYNERGENIX DIAGNOSTICS | F3: JOEY JENKINS | G3: 202-607-3875 | H3: jenkinslifetree@gmail.com | I3: Fri 7:00 PM | J3: MD based has the ngs machine and do the immune deficiency test, medicare licensed, and accept patients from most states, asked to send email meeting fri | K3: set a meeting next thursday same time 2:00 PM, he will Out source it for one of his parnter to do it in his lab and get the reimbursements and pay for us , I will send him the email and everything now , we discussed the payment cycle as upfront would be difficult for them , 50% and they will circle back and get back to us , 03/26/2026 , someone try to reschedule the meeting , we agreed on 50% we are still agreeing on the capacity 12- 17 - 25 patients, he still waiting on some capital to fund this project 3/30, i spoke with him and he said that he want to work with us and want to built trust he want us to send atleastsome leads to get started then he will pay, itold him about the 50percent but he said still to much , i told hime about the uti he said he can doi it and it less pricy so we cant start with it if we have ready pts and if he finds our work went well he will work with us the ngs and pgx meeting on friday 12pm est | M3: 46223.763 | O3: FALSE | Q3: 1174419758
A4: ORT | B4: Selene | D4: 46231 | E4: EPIC PROSTHETICS AND ORTHOTICS LLC | F4: JAKE COBURN DAVIS | G4: 801-820-0045 | H4: jake@epicpo.com | I4: =HYPERLINK("https://calendar.google.com/calendar/u/0/r/eventedit/Mm8zMmNqNmJidG8zZWZyODlubXNtMzFydGUgYzM5ZjIxNjY2YTJjNzBkNjQ0MDI0YmQyOWM3ZmM5ODM3OTY2MmY3OTJlNWEwNDdjZGIzNTdhNDJiM2M1N2QwNEBn?pli=1", "FRI 8:00 PM") -> FRI 8:00 PM | J4: UT Based ,supply ORT ,Mediacre liscenced ,supply locally said he does marketing himself but interested to know more said to give him a call at 11 am his time on friday 7/28 | Q4: 1629722889
A5: Lab | B5: Jane | D5: 46233 | E5: ADVANCED LABORATORY SERVICES INC. | F5: JASBIR ARORA JASBIR ARORA | G5: 484-324-6680 | H5: jasbir.arora@advanced-lab.com | I5: =HYPERLINK("https://calendar.google.com/calendar/u/0/r/eventedit/NjdvNWowNGZkdGtwZmtxMzk2MnM5c3F0ZTIgYzM5ZjIxNjY2YTJjNzBkNjQ0MDI0YmQyOWM3ZmM5ODM3OTY2MmY3OTJlNWEwNDdjZGIzNTdhNDJiM2M1N2QwNEBn", "Wed 10:00 PM") -> Wed 10:00 PM | J5: ,Pa based do pgx, can bill medicare, but never billed for pgx able to do that , work all stattes accept for the ny will get licsence by end of the year fopr ny, meeting on wednesday to discuss with his team | K5: he apolagized and will reschedule on my calender by this week | M5: 46240.741 | Q5: 1265365829
A6: Lab | B6: Selene | D6: 46239 | E6: MICROSEQDX | F6: RAHUL SHARMA | G6: 225-573-2690 | H6: rsharma@microseqdx.com | I6: =HYPERLINK("https://calendar.google.com/calendar/u/0/r/eventedit/M3ZvM2Q1M2JiazRjc285MGZmZWU4Z2w2NjcgYzM5ZjIxNjY2YTJjNzBkNjQ0MDI0YmQyOWM3ZmM5ODM3OTY2MmY3OTJlNWEwNDdjZGIzNTdhNDJiM2M1N2QwNEBn?pli=1", "FRI 11:00 PM") -> FRI 11:00 PM | J6: TX Based, accepts nationwide medicare patients does UTI,PGX meeting TUES 9 PM pm our time 8/5 | K6: He provides UTI PGX inhouse and NGS to his partner lab ,he has an issue with telemedicine and wants PCP and wants the same person prescribing the test to prescribe the medicine ,he said he can start with any test but he has an isuue with the prices he sees it high he says he only pays 30 percent marketing fee, he said he wants to work as a refrence lab and find another lab to bill. Next meeting we will ask if he read the codes and checked with the reimbursemnet and will explain that we do tele only and explain to him the overhead costs (telemdicine service ,ads,guide patient ) meeting next tuesday 9 pm 8/11sent him samples and marketing plan he has an issue with the TMS he wants the TMS to prescribe medication to the patient and he has issues with the pricing so next time we will hope on a call with mike and we will discuss that TMS is not an issue and we provide (ads,kitchasing,TMS) and thats its not expensive | M6: 46248.797 | Q6: 1033037254
A7: MLA | B7: Jimmy | D7: 46241 | E7: Life assure | F7: Brandon | G7: Ph: 204-982-0095 | H7: brandon.leblanc@lifeassure.com | I7: THU 8:00 PM | J7: Good afternoon, A colleague passed your contact information to me because you reached out about working together. I'm interested in learning more about how Prime Ad and Life Assure could explore a partnership. Do you have time for a call tomorrow or early next week to discuss this?
A8: ORT+CGM+LYMPH W | B8: Nora | D8: 46241 | E8: 86TH STREET COMMUNITY PHARMACY CORP. | F8: ABAID CHEEMA (President) | G8: (347) 543-3955 | H8: 86thstpharmacy@gmail.com | I8: Mon 7:00 PM | J8: NY based. He supplies ORT, CGM, and Lymph. He has Medicare and PPO and can ship nationwide 8/7 He said Mondays are a bit busy so rescheduled for tom at 6 pm 8/10 | Q8: 1093732513
A9: Lab | B9: Jane | D9: 46244 | E9: ORANGE COUNTY LABS INC. | F9: Bryan Muhlenbruch | G9: 714-519-1466 | H9: bm@orangecountylabs.com | I9: =HYPERLINK("https://calendar.google.com/calendar/u/0/r/eventedit/NWdmZDZpbjVjcGxidGhjcDUydmNwaDlyOHMgamFuZS5teWxlcy53aXpAbQ", "Wed 10:30 PM") -> Wed 10:30 PM | J9: ca based do genetic testing,immune and uti,pgx,accept medicare pts nv ca mi fl az, tx, he can apply for credation for other states according to the capacity if it needs, meeting tomw 10:30pm | K9: rescheduled for tomowrow 10;30 | M9: 46253.891 | Q9: 1023439809
A10: Lab | B10: Jimmy | D10: 46245 | E10: DE LA LUZ LABORATORY LLC | F10: MARIA ESMERALDA AMARO HERNANDEZ | G10: 312-415-7097 | H10: mariaeamaro700@gmail.com | I10: THU 8:00 PM | J10: She can do immune, PGx and UTI and accepts medicare and private insurance PTs | Q10: 1326972274
A11: ORT+CGM | B11: Selene | D11: 46247 | E11: GUARDIAN ANGEL DME | F11: MD FAYSAL AHMED | G11: 213-263-1687 | H11: pbreliefmedicalsupply@gmail.com | I11: =HYPERLINK("https://calendar.google.com/calendar/u/0/r/eventedit/MjlvM2kza2xiaDZ2dThybGNva2hmamRkcG8gYzM5ZjIxNjY2YTJjNzBkNjQ0MDI0YmQyOWM3ZmM5ODM3OTY2MmY3OTJlNWEwNDdjZGIzNTdhNDJiM2M1N2QwNEBn?pli=1", "Mon 6:30 PM") -> Mon 6:30 PM | J11: CA Based ,supply ORT, CGM ,Mediacre liscenced ,ships nationwide ,interested to know more said to give him a call at 6.30 pm our time mon 8/13 | Q11: 1922806330
A12: Lab | B12: Nora | D12: 46248 | E12: PRIME DIAGNOSTICS LAB INC. | F12: SYEDA HINA SHAKIL (CEO) | G12: (425) 444-6076 | H12: primelabdiagnostics2019@gmail.com | I12: Fri 11:00 PM | J12: Based in MI. They do UTI testing only and they ship in Michigan. They can bill Medicare and other Michigan-based private insurances. | Q12: 1093351470
A13: ORT+CGM | B13: Selene | D13: 46251 | E13: VELORA DME SOLUTIONS LLC | F13: AZAR TALIBOV | G13: 856-347-7880 | H13: johnalpha601@gmail.com | I13: =HYPERLINK("https://calendar.google.com/calendar/u/0/r/eventedit/NjM1Y2tqZjY0cTd2dW9lZWc1anQ4dXN0bjcgYzM5ZjIxNjY2YTJjNzBkNjQ0MDI0YmQyOWM3ZmM5ODM3OTY2MmY3OTJlNWEwNDdjZGIzNTdhNDJiM2M1N2QwNEBn?pli=1", "Tue 8:00 PM") -> Tue 8:00 PM | J13: NJ Based ,supply ORT, CGM ,Mediacre liscenced ,shipslocally but will consider nationwide ,interested to know more said to give him a call at 8.00 pm our time tues 8/13 | Q13: 1184554750
A14: Lab | B14: Nora | D14: 46251 | E14: DIAGNOSTIC TESTING SOLUTIONS INC | F14: NADEEM AKHTAR | G14: (773) 853-0883 | H14: dnask1@gmail.com | I14: TUE 9:30 PM | J14: Based in IL. They do UTI testing and they accept Medicare patients. They also have nationwide shipping 8/17 He had an emergency will cb tomorrow to reschedule 8/18 | Q14: 1174278238
A15: ORT+CGM | B15: Jane | D15: 46251 | E15: WOUND BOX LLC | F15: JASON/ ADAM JOHN MEIERHOFER | G15: 855-968-6326 | H15: jason@woundbox.com | I15: =HYPERLINK("https://calendar.google.com/calendar/u/0/r/eventedit/NTFnZmo4YWhzb3JmNmt2ZThhNTNhZGttb2MgamFuZS5teWxlcy53aXpAbQ", "Tue 10:00 PM") -> Tue 10:00 PM | J15: Tx based, said he can supply ort,cgm, and i told him our volume of cgm is more, can ship any place, meeting 8/17 | Q15: 1831055482
A16: Lab | B16: Jimmy | D16: 46252 | E16: MNM LABORATORY CONSULTING, LLC | F16: MASHUD OGUNLAJA | G16: 424-999-8698 | H16: info@mnmlabCONSULTING.com | I16: FRI 8:00 PM | J16: NGS, UTI, PGx can accept medicare PT | Q16: 1073367389
A17: ORT+CGM | B17: Selene | D17: 46253 | E17: WELLVORA LLC | F17: FAIZAN KHAN | G17: 949-304-0361 | H17: frksrkhan2@gmail.com | I17: =HYPERLINK("https://calendar.google.com/calendar/u/0/r/eventedit/N2I0bXJxc3VkNGFrZWFyajVxZmMwMjU3ODcgYzM5ZjIxNjY2YTJjNzBkNjQ0MDI0YmQyOWM3ZmM5ODM3OTY2MmY3OTJlNWEwNDdjZGIzNTdhNDJiM2M1N2QwNEBn?pli=1", "FRI 4:00 PM") -> FRI 4:00 PM | J17: CA Based ,supply ORT, CGM ,Mediacre liscenced , nationwide ,interested to know more said to give him a call at 4.00 pm our time FRIDAY 8/13 | Q17: 1528985488
A18: ORT | B18: Nora | D18: 46253 | E18: NUA AESTHETICS LLC | F18: NAYMA LABARCA | G18: (407) 515-7755 | H18: nayma@nuaesthetics.com | I18: THU 9:00 PM | J18: Based in FL. They supply ORT and they have Medicare and Oscar. Local shipping in FL for now 8/19 | Q18: 1689528770
A19: ORT+CGM | B19: Jane | D19: 46253 | E19: VITALFORT LLC | F19: MUHAMMAD KHAN | G19: 917-525-2517 | H19: mr.mianzohaib@gmail.com | I19: =HYPERLINK("https://calendar.google.com/calendar/u/0/r/eventedit/NG04MDVyOGo1bzVnMW03cWJwdHN1bTluamwgYzM5ZjIxNjY2YTJjNzBkNjQ0MDI0YmQyOWM3ZmM5ODM3OTY2MmY3OTJlNWEwNDdjZGIzNTdhNDJiM2M1N2QwNEBn", "Thu 11:00 PM") -> Thu 11:00 PM | J19: Ga based, supply ort , cgm, bill medicare . ship all states, meeting tomw 11 pm 4 pm est tomw
A20: Lab | B20: Nora | D20: 46253 | E20: BENDA HEALTH EDUCATION AND TESTING SERVICES LLC | F20: BENDU DAWOLO | G20: (281) 836-1869 | H20: bendacpr@gmail.com | I20: THU 6:00 PM | J20: Based in WI. They do UTI testing. They accept Medicare patients and operate in WI for now 8/19 | Q20: 1316777543
A21: Lab | B21: Nora | D21: 46253 | E21: WELCARE DIAGNOSTICS LLC | F21: RINABEN VAGHELA MAKANI | G21: (215) 285-8545 | H21: info@welcaredx.com | I21: FRI 9:00 PM | J21: Based in NJ. They have UTI, Immune, and PGx. They accept Medicare and private insurances and they operate in NJ and PA 8/19 | Q21: 1285338731
A22: Lymphadema | B22: Jasmine | D22: 46253 | E22: STRATEGIC ACCESS INTERNATIONAL LLC | F22: Rhonda Mitchell | G22: 202-810-1821 | H22: rhondacmitchell@gmail.com | I22: Mon 9:30 PM | J22: GA based, has lymphedema currently but in the process of getting ORT/CGM , can accept most private insurances and in the process of obtaining the PTAN code for medicare. | Q22: 1568380384

Sheet Follow Ups
A1: SUB | B1: Opener | C1: Status | D1: Date Added | E1: Company Name | F1: Authorized Person | G1: Phone | H1: EMAIL | I1: Meeting Time | J1: Opener Summary | K1: George's Notes | L1: Auto Scheduler | M1: Last Call | N1: Action | O1: Checkbox | P1: Log | Q1: NPI
A2: Campaigns | B2: Selene | C2: Follow Up | D2: 45707 | E2: PROMED SUPPLIES | F2: Zahid James | G2: 215-954-0877 | H2: promed239@gmail.com | I2: Fri 8.00PM | J2: - done from medicare inspection will work i month from now , dme cgm al states pcp tele med fri 21st 1 pm est 8 pm our time -selene 2/19 - Yayyyyyy he got his PTAN and he said he was looking for our contact he wnats to start i resent the email and calender invite meeting today 5 pm est 11 pm our time -selene 3/27 - He was very sick and wanted us to call him 10 am tmrw or 10 am wed-selene 3/28 - He wants medicare to change his number and then start he will return to us by fri about medicare number -selene 4/15 - yayyy Medicare changed his number and everything is all set cb Mon 19th 12 pm EST -selene 5/13 waiting for funds -WILL CB IN AN HOUR 7/28 - broke said not ready to do it he will contact us -selene 8/8 - said to send prices and give him a cb on fri 1/20 -no longer doing DME 8/4 | K2: - send a price list 08/29/2025 - DOC 2/5 VM - schedule a google meet next week 8:30 our time, i sent the proposal + prices again - ben, no answer -VM FULL - ben vm 7/20 | M2: 46223.802 | N2: VM | O2: FALSE | Q2: 1649038878
A3: ORT | B3: Selene | C3: Follow Up | D3: 45713 | E3: REGAL MEDICAL SOLUTIONS INC | F3: Tara | G3: 678-701-7310 | H3: carlytdme2@gmail.com | I3: Fri 8.00:PM | J3: - GA basesd I spoke to tara she works with PCP/ Telemed all states CGM DME and she wanted to know reviews about us and asked if we have US bank acount meeting friday at 1 pm est and 8 pm our time she will dicuss with her partners -selene 2/25 - Meeting Tmrw at 27th feb 3.30 est and 10.30 or time meeting with her business partner -selene 2/26 - cb next monday she said she will think about it and i resent the email-selene 7/31 | K3: Spoke to one of her partners but the other meeting keeps getting reschedule, I should call to follow up around the 10th of March. DOC 3/27/2025 Said that our prices are a bit high, but they aren't that interested at the moment. said she will get back to me Doc (12/11/2025) ,can't reach her - DOC 2/5 VM dis 7/20 | M3: 46223.802 | N3: VM | O3: FALSE | Q3: 1053144022
A4: ORT | B4: Jane | C4: Follow Up | D4: 45714 | E4: Allhealth & Care Medical Supply Inc. | F4: Robert Binyaminov | G4: 917-957-2766 | I4: Mon 5:00 PM | J4: Medicare licensed, DME & CGM, NY based but can do all states, PCP, he was very interested in the contract as he wants to review it with his attorney | K4: waiting for his PTAN DOC 13/3/2025. DOC 4/4/2025 still in the process did fingerprint, any time now he will receive his PTAN. Received his PTAN and will talk with his biller to finalize compliance matters today DOC 4/24/2025 VM (12/11/2025) VM - ben | M4: 46085.887 | O4: FALSE | Q4: 1568221281
A5: ORT | B5: Jane | C5: Follow Up | D5: 45737 | E5: SUNRISE MEDICAL SUPPLY CORP | F5: Liya Yusupova | G5: 917-763-9518 | H5: info@ameristarbilling.com | I5: Mon 5:30 PM | J5: NYBASED, SUPPLU DME ,CGM MEDICARE LICENSED AND, SHE WANT TO SHIP TO ALL STATES BUT THINKS THAT SHER NEED LICESEND, IT OKAY U CAN SEND THEM ALL STATES, PCP, MEETING 5:30 OUTIME, 11 30 AM 3/21 | K5: Finally answered and asked me to call next week same time because her partner is away VM (12/08/2025) Full VM - ben sent an email | M5: 46085.853 | O5: FALSE | Q5: 1639847205
A6: ORT+CGM | B6: Selene | C6: Follow Up | D6: 45754 | E6: IK-MED LLC | F6: Sheikh Aftab | G6: 703-640-8784 | H6: ASAD149@GMAIL.COM | I6: Tue 10:30 PM | J6: Medicare liscenced , nationwide, PCP ,ORTCGM he said he takes between 50 to 100 pts per week meeting 4/8 tuesday 4.30 est 10 .30 our time -selene 4/7 - i gave him a call today he said that he is really interested and to give him a call tmrw at 11.30 am his time 4/24 - he hung up seems NI -selene 4/29 - cb next mon 1 -selene 11/25 | K6: We will have a second call tomorrow to discuss the proposal after we send the pricelist. DOC 4/9/2025 No answer 3 times. DOC 4/10/2025 Call tomorrow. DOC 4/11/2025 No answer DOC 4/14/2025 Will talk later this week on Friday. DOC 4/18/2025. Could start trial on Monday, I will send the contract and the pricelist again and call on Monday. Really not serious, instant VM DOC 4/23/2025 - DOC 2/5 VM - was out of town, wants an email, schedule a google meet for friday 8 pm -said to call him 11:30/12 tomorrow - ben - full vm 7/20 | M6: 46223.802 | O6: FALSE | Q6: 1518788249
A7: ORT+CGM | B7: Ben | C7: Follow Up | D7: 45761 | E7: Family Alliance Medical Equipment And Supply Company | F7: Audrey Fletcher / Spoke to Evan | G7: 267-272-7791 | H7: f.alliancehomecare@gmail.com | I7: Thu 8:00:PM | J7: PA Based. AlL States, went over our email seems v interested wants an email and a call tuesday same time 8/21 | K7: I spoke with Evan, her office manager. Very interested and we will talk again in a video call for the demo. VM - BEN recheduled with evan spoke to audrey about meeting with evan VM | M7: 46248.746 | O7: FALSE | Q7: 1033979000
A8: ORT+CGM | B8: Selene | C8: Follow Up | D8: 45785 | E8: Nex Medical Services Inc | F8: Ms Michelle (Supervisor ) | G8: 281-583-1810 404 Elais | H8: mg@nexmeds.com er@nexmeds.com | I8: Mon 6:00:PM | J8: - I spoke to Michelle supervisor she said Medicare liscenced ,ORT CGM can work all states she said they worked several counties i sent an email -selene 5/7 - I spoke to michelle (ext 402) or could be transferred she said we could have a meeting on Monday around 10 am cst 6 pm our time she said she and her partner handle the business -selene 5/8 - cb next mon 6/11 - spoke to michelle she said to resend the prices and give her a cb on wednesday and she will send it to her partner -selene 6/27 - cb monday sent email to partner 8/7 | K8: We spoke and covered everything, we will send a prive list and talk again on Friday. DOC 5/16/2025, Said she sent the price list to her Partner and we will touch base again on Wedensday instead becuase he isn't available today. - DOC 2/5 VM , set an appointment for next tuesday at 11:00 (google meet ) , she wants us to call back later today as she is waiting for elias to come from an appointment 03/10/2026 | M8: 46091.768 | O8: FALSE | Q8: 1790930857
A9: ORT+CGM | B9: Selene | C9: Follow Up | D9: 45847 | E9: DULUTH MEDICAL SUPPLIES LLC | F9: Raed Hareb | G9: 706-351-5894 | H9: duluthmedicalsupplies@gmail.com | I9: Wed 9:00:PM | J9: - GA Based just got their PTAN and works Part B and PPO really interested and said wants to speak with us with his partner meeting 2 pm est 9 pm our time today 7/9 | K9: interested meeting tomorrow | O9: FALSE | Q9: 1790520120
A10: SUB | B10: Selene | C10: Follow Up | D10: 45847 | E10: Entourage Me UAE | F10: Neil Laithy | G10: 401-206-0481 | H10: nlaithy@gmail.com or zoeyweedspc@gmail.com | I10: Wed 5:00:PM | J10: - Connected via Linkdin asked if we worked in ACA or genetics gave phone number to george so he can talk to him -selene 7/9 | K10: we spoke about ACA & Genetic testing , Really good Guy | O10: FALSE
A11: ORT+CGM | B11: Selene | C11: Follow Up | D11: 45875 | E11: SML MEDICAL SUPPLIES, INC. | F11: SAMIR RAMADAN | G11: 909-559-7200 WA | H11: sawad@smlmedicalsupplies.com | I11: Wed 7:30:PM | J11: CA BASED , MEDICARE LICENSED, SHIP ALL STATES,CGM, ORT wants to know more about prices meeting 7.30 OUR TIME 9.30 PDT HIS TIME -SELENE 8/6 | K11: Send all the Info regarding CGM VM NOT SETUP. ben | M11: 46183.848 | O11: FALSE | Q11: 1558826628
A12: ORT+CGM | B12: Selene | C12: Follow Up | D12: 45875 | E12: SML MEDICAL SUPPLIES, INC. | F12: Sameh Awad | G12: 909-559-7200 WA | H12: sawad@smlmedicalsupplies.com | I12: Wed 7:30:PM | J12: CA BASED , MEDICARE LICENSED, SHIP ALL STATES,CGM, ORT wants to know more about prices meeting 7.30 OUR TIME 9.30 PDT HIS TIME -SELENE 8/6 | K12: Send all the Info regarding CGM ben dnc | M12: 46085.896 | O12: FALSE | Q12: 1558826628
A13: Campaigns | B13: Jane | C13: Follow Up | D13: 45890 | E13: PCP ( DDV Provided ) | F13: Ricky Sharma | G13: Teams | I13: Thu 9:30PM | J13: he will provide the DDV lower payouts than gary thomas | O13: FALSE
A14: Campaigns | B14: Selene | C14: Follow Up | D14: 45890 | E14: uk boliers expert | F14: Qeiser Nazir | I14: Fri 1:00PM | J14: we talked about the chance that we can work together , he gave me dialer and will get me data | K14: he gave us info about the boilers campaign & dialer information | O14: FALSE
A15: ORT+CGM | B15: Selene | C15: Follow Up | D15: 45894 | E15: AMASOL MEDICAL EQUIPMENT & SUPPLY LLC | F15: Moses Carayol | G15: 914-582-2764 | H15: amasolmedicalsupply@gmail.com/ john | I15: Tue 10:30PM | J15: NY Based Medicare liscenced ships all states PCP Telemed ORT ,CGM wants to know the prices Meeting Tuesday 3.30 pmest 10.30 pm our time -selene 8/25 | K15: send all the info on the ORthopedic Braces + Price list + a sample from pcp order and telemed Order Called him 09/09 (VM ) - Spoke to him he said to resend email with prices -selene 2/5 Full VM / sent email - ben vm 7/20 | M15: 46223.803 | O15: FALSE | Q15: 1639503121
A16: ORT+CGM | B16: Jane | C16: Follow Up | D16: 45904 | E16: Jk Care Supplies Llc | F16: Ismail Khan | G16: 646-920-5833 | H16: ismail290k@gmail.com / Kashif.khan15504@gmail.com | I16: Fri 5:00PM | J16: Licensed, all states, DME and CGM, he was excited to talk tomorrow | K16: meeting on wednesday 11:00 am EST , He will be texting the other partners email and we could proceed afterwards VM -ben | M16: 46112.898 | O16: FALSE | Q16: 1952279325
A17: ORT+CGM | B17: Ben | C17: Follow Up | D17: 45919 | E17: Dmg Wellness Inc. | F17: Gregory Ihenacho | G17: 323-676-5360 | H17: dmgwellness2019@gmail.com / david@dmgwellness.com | I17: Mon 10:00PM | J17: medicare all states, Spoke to patner, David, interested, wants email with all info 9/19 BE BACK NEXT WEEK 2/26 | K17: Ben Arthur, send him our process in braces + prices for PCP + the lcodes that we are using ( already written in the pdf that contains the pricing ) L 0647 L 1812 L1820 this is the L codes that he is using , he is interested in braces not CGM , and he is even more interested in the lymphadema wraps be back next week - ben - DAVID FORGOT EVERYTHING, consider as new unless he remembered - ben | M17: 46112.963 | O17: FALSE | Q17: 1568089548
A18: Vacation DNC Camapign | B18: Jane | C18: Follow Up | D18: 45925 | E18: Intellegent Healthcare llc | F18: Adrian | G18: 305-560-3285 | J18: US BASED , TARGET THE US AND CANADA CUSTOMER , PROVIDE DDV AND TRAININD WANTS TO START WITH 3 AGENTS | K18: we spoke over the phone and he sent me the details on whatsapp | O18: FALSE
A19: ORT | B19: Ben | C19: Follow Up | D19: 45708 | E19: A1 Medical Equipment Inc. | F19: Dallas Powers | G19: 616-835-3304 | H19: DallasRpowers@yahoo.com | I19: Fri 9.00:PM | J19: - Medicare licensed, CGM mainly but also does bracing, all states, PCP mainly but said if you say that I can also do telemed as I can do that as well | K19: Interested, CGM CPL 11:00 am, Comparison between Pay per hour (lead generation) ( client would be doing the chasing ) and normal of 9-11 patients per month full VM -ben hungup, sent email , ben | M19: 46183.848 | O19: FALSE | Q19: 1265051916
A20: ORT + Lymphedema | B20: Selene | C20: Follow Up | D20: 45992 | E20: DYNAMEDICS MEDICAL SOLUTIONS, INC | F20: SAM OBINNA SONNY ECHENDU | G20: 919-995-0554 | H20: dmedsolutions@gmail.com / dynamedicshcs@gmail.com | I20: Tue 8:30PM | J20: NC Based, medicare liscenced ships nationwide , supply ort ,lymph meeting tuesday 1.30 est 8.30 our time 12/1 - Meeting changed to next mon 9 pm because he said he needs to fix problems at work 12/2 | K20: 12/10/2025 9 pm our time he didn't receive the email and i got a different email from him he will review and we will touc base on wednesday same time seems to be NI - ben didn't have time to read the email due to internet problems vm full, ben full vm | M20: 46223.804 | O20: FALSE | P20: didn't have time to read the email due to internet problems | Q20: 1902542756
A21: IMMUNE | B21: Jane | C21: Follow Up | D21: 45939 | E21: ADVANTAGE DIAGNOSTICS CLINICAL LABORATORY LLC | F21: POLINA GENKIN | G21: 347-462-4949 | H21: polina.g@advantagediagnosticlaboratory.com, | I21: Fri 5:00PM | J21: she is nj based, serve alll states, bill medicare, she supply immuno deficiency , PCR,UTI polina.g@advantagediagnosticlaboratory.com, MEETING TOMW 10 AM,HER TIME 5 PM OUR TIME, | K21: interest in the uti only, she will call me tomorrow sent her an email follow up on thursday 10/16 | O21: FALSE | Q21: 1497486880
A22: ORT + Lymphedema | B22: Jane | C22: Follow Up | D22: 45980 | E22: KARMA7 MEDICAL SUPPLY LLC | F22: Roman Krive | G22: 847-454-7085 ext 101 | H22: office@k7supply.com | I22: Fri 7:00 PM | J22: IL BASED, MEDICARE LICSEND, SHIP TO ILL WI, IN BUT WILLING TO DO,asked about the link for shipping meeting 5:30 pm our time | K22: interest in the uti only, she will call me tomorrow sent her an email follow up on thursday 10/16, she said our prices was too high put wan toknow the uti pts prices | M22: 46223.75 | O22: FALSE | Q22: 1477024347
A23: IMMUNE | B23: Selene | C23: Follow Up | D23: 45981 | E23: BIO SYSTEMS LABORATORY, LLC | F23: DAMIEN FRALIN | G23: 972-951-6530 | H23: gorilla2018@yahoo.com | I23: Fri 9:00 PM | J23: TX Based, Mediacare Liscenced , Accept All States patients does immuno genetic testing does the tests with telemed has a concern if the bill is not extended meeting tmrw 9 pm 1 pm cst -selene 11/20 | K23: He is well aware about process doesnt want to pay upfront wants to pay little or when the kits arrive at his doorstep | O23: FALSE | Q23: 1275364853
A24: ORT + Lymphedema | B24: Jane | C24: Follow Up | D24: 45985 | E24: BINSON'S FLORIDA, LLC | F24: JAMES E BINSON | G24: 586-933-7598/ matt 5867552300 ext4464/ mattp@binsons.com/ sherry ext 4616 | H24: jimmyb@binsons.com | I24: Tue 6:30PM | J24: Fl based, medicare licsensend supply ort and lymhadema wraps, ship all states, send email, meeting tomw 6:30 our time | K24: ben can you send the price list ( 2 modules + sigvaris catlogue ) they will respond back to the email with their convenient time meeting on friday12/5/2025 / voice mail 01/08/2025 VM -ben | M24: 46094.862 | O24: FALSE | Q24: 1386886554
A25: IMMUNE | B25: Selene | C25: Follow Up | D25: 45987 | E25: LABPHARMA, LLC | F25: OLIVER MIGUEL | G25: 844-522-2031/ (786) 426-3205 | H25: omiguel@labpharmacorp.com | I25: Tue 9:30PM | J25: FL Based , Mediacre liscenced accepts patients nationwide does immune defiency genetic testing meeting tuesday 9.30pm 2.30 est 11/26 | K25: he doesn't do any Genetic testing ( he doesn't have the equipment for it ) but he might be able to do UTI / blood tests / covid and influenza Meeting next friday same time 9:30 our time - vm 7/20 | M25: 46223.806 | O25: FALSE | Q25: 1437917556
A26: ORT | B26: George | C26: Follow Up | E26: Cabretta Llc | F26: SARAH WAGGONER | O26: FALSE | Q26: 1144950106
A27: ORT | B27: George | C27: Follow Up | E27: Cabretta Llc | F27: JILL HAMAKER | O27: FALSE | Q27: 1144950106
A28: ORT+CGM | B28: Selene | C28: Follow Up | D28: 46002 | E28: VERINA CO MEDICAL SUPPLIES LLC | F28: RAMY WAHBA | G28: 818-479-1585 | H28: info@verinacare.com | I28: Tue 8:30PM | J28: - CA BasedSupplies ORT CGM Medicare via another DME he said he is really interested in getting referrals and wants to talk to us and know more about us meeting next tuesday 10.30 pst 8.30 our time 12/11 | O28: FALSE | Q28: 1053165191
A29: IMMUNE | B29: Jane | C29: Follow Up | D29: 46030 | E29: LIFECARE LAB | F29: ALAA KAHALA | G29: 346-317-2949 | H29: abd_nyk2003@yahoo.com | I29: Thu 11:00 PM | J29: Tx based medicare license , do immuno, pgx and uti, accept pt from all states, he said will give us a call with hs director today asked to send email | O29: FALSE | Q29: 1568358547
A30: IMMUNE | B30: Jimmy | C30: Follow Up | D30: 46045 | E30: US LAB HOLDINGS LLC | F30: VINCENT VITATOE | G30: 816-309-0569 | H30: VINCENT@MODUSlaboratorIES.COM | I30: THU 7:00 PM 29/03 | J30: TX Based UTI - AND FOR NGS PGX CAN DO WITH REFRENCE LAB (WANT TO KNOW HOW MANY WE CAN PROVIDE FIRST) | K30: he is not convinced that he should pay an upfront payment he wants to pay weekly after receiving the Patients, Propability 25%, Doc 02/04/2026 he wants to send this to their billing people and then touch base with the reference lab and try to follow up next thursday 02/12/2026 , send a calender invite for next thursday Chad@MODUSlaboratorIES.COM , Vasco@MODUSlaboratorIES.COM,, we sent him the documents needed they will call us today or tomorrow 02/26/2026 , will send chad information about a person that can help them with the validation and instrument set up , 04/02/2026 i spoke to chad he said that they are still interested but maybe the needed a month to move forward and i sent him a contact info to help him with anything that he needs | M30: 46114.836 | O30: FALSE | Q30: 1013678333
A31: ORT+CGM | B31: Ben | C31: Follow Up | D31: 46057 | E31: LIMITLESS MEDICAL SUPPLIES LLC | F31: SALEF SOBHO | G31: 470-567-6727 | H31: saleh.soboh@yahoo.com | J31: Very interested seems to know what he's doing 2/2 | K31: VM - ben sent email VM - ben vm, ben 7/20 | M31: 46223.948 | O31: FALSE | Q31: 1538033469
A32: IMMUNE | B32: Jimmy | C32: Follow Up | D32: 46044 | E32: PREMIER LAB SOLUTIONS BAKERSFIELD LLC | F32: PETER SIMMONS | G32: 781-626-1212 | H32: peter.simmons@lemedix.com | I32: =HYPERLINK("https://calendar.google.com/calendar/u/0/r/eventedit/N2tzN2JxMzhkNGltMDhyNW05OHNuMDF0azkgYzM5ZjIxNjY2YTJjNzBkNjQ0MDI0YmQyOWM3ZmM5ODM3OTY2MmY3OTJlNWEwNDdjZGIzNTdhNDJiM2M1N2QwNEBn", "THU 6:00 PM") -> THU 6:00 PM | J32: He does UTI, and Can do immune through another lab, can accept medicare PT and accept from all states "Called him and reshcedled the meeting to tomorrow 6:00 pm 2/12/26 (2/11/26 6:07) Meeting rescheduled to 9:00 pm our time 2 pm his time George called him and left him a VM and I called him and he did not pickup 5:09 He did not pickup 1/26/26 5:08 | K32: we need to my seq, Pgx , they need to do gene validation, we need to the machine that they are using and gene validation to do this CPT code , two California and one Chicago validation and sample report and what machines required, lab set up and validation for the NGS, we spoke again on the 12th and he is interested to do NGS if he understand the machinary and lap setup needed alongside the validation VM - ben , I will connect him with dr ajaez to on whatsapp and connect him together | M32: 46155.964 | O32: FALSE | Q32: 1548978034
A33: ORT+CGM | B33: Ben | C33: Follow Up | D33: 46056 | E33: ONE O SEVEN LLC | F33: MARZOOQ LAKHANI | G33: 713-498-5462 | H33: oneosevendme@gmail.com | I33: Thu 5:00 PM | J33: CGM & ORT, Med part B, starting in tx, They can work all states, he said he preferrs if a higher percentage would be from his state (texas) to not flag medicare, seems to have experience | K33: speaking on whatsapp auto vm, ben | M33: 46183.893 | O33: FALSE | Q33: 1174483572
A34: IMMUNE | B34: Ben | C34: Follow Up | D34: 46080 | E34: YOUR LAB TEST TX | F34: CLARISSIA JONES | G34: 214-684-9182 | H34: adisyenterprise@gmail.com | I34: Wed 8:30 PM | J34: Insurance, Only Texas ,Not sure of the tests she can do + Renewing her licenses, | K34: she will act as a middle man | M34: 46080.994 | O34: FALSE | Q34: 1265173389
A35: IMMUNE | B35: Ben | C35: Follow Up | D35: 46084 | E35: ALBANYLABS LLC | F35: SUMANTA GOSWAMI | G35: 347-613-3322 | H35: sumanta.goswami@albanylabs.com, / info@albanylabs.com | J35: Rescheduled with him | K35: Calendly. no ngs but he knows people | M35: 46223 | O35: FALSE | Q35: 1770232423
A36: IMMUNE | B36: Jimmy | C36: Follow Up | D36: 46083 | E36: RUSH LAB LLC | F36: WAQAS MIRZA | G36: 312-520-4582 | H36: wwmirza@gmail.com | I36: MON 11:30 PM | J36: "Immune - UTI - PGx - CGx wwmirza@gmail.com azzedine13@yahoo.com" | K36: he has a dme company and a adam travel agency ABDo ibrahim | M36: 46084.016 | O36: FALSE | Q36: 1144173832
A37: IMMUNE | B37: Selene | C37: Follow Up | D37: 46064 | E37: PATRIOT MEDICAL LABORATORIES LLC | F37: SOMBABU MULLAPUDI | G37: 240-422-4164 | H37: sam@ciandx.com | I37: THU 10:30 PM | J37: - MD Based, Medicare liscenced , Accepts nationwide does NGS meeting tmrw 10.30 our time -selene 2/11 - called x2 no anwer 3/18 | K37: tuesday between 10 - 12 , face to face meeting , so he would revise with his team and discuss everything during the meeting - I spoke to sam he said that our gmail email is not professional and he is concerned with the upfront pricing and wanted to discuss it in tmrw meeting-selene 3/5 - sent email for UTI PGX NGS 7/20 | M37: 46223.823 | O37: FALSE | Q37: 1710300579
A38: IMMUNE | B38: Ben | C38: Follow Up | D38: 46066 | E38: GP QUEST HEALTH CENTER LLC | F38: ELAINE PONS | G38: 786-205-7062 | H38: gpquesthealthcenter@gmail.com | I38: Tue 8:30 PM | J38: FL Based NGS, Mediare B, All states 2/12 | K38: they spilled the coffee in the meeting, they also don't know if they have the right machinary to do the NGS testing , and didn't know if they have it or not they need us to send him the machinary | M38: 46070.871 | O38: FALSE | Q38: 1881491447
A39: IMMUNE | B39: Selene | C39: Follow Up | D39: 46063 | E39: PROLINE LABS | F39: JEFFREY RODRIGUEZ | G39: 915-494-2611 | H39: PROLINELABS@gmail.com | I39: WED 6:30 PM | J39: TX Based, Medicare liscenced accepts nationwide he said he is getting the NGS but he seems new to the work but very interested and wants to know the prices meeting tmrw 6.30 pm our time wed -selene 2/10 | K39: what type of license do you need , High complexity, tomorrow 11:00 am Standard time , 10 am tomorrow 02/13/2026 busy wants us to call him in an hour (busy schedule call him tomorrow) - ben - vm 7/20 | M39: 46223.83 | O39: FALSE | Q39: 1427812916
A40: IMMUNE | B40: Selene | C40: Follow Up | D40: 46057 | E40: SYNERGY DIAGNOSTIC LAB | F40: ADNAN SADIQ/Nadeem (decision maker) | G40: 732 470 4310 | H40: waytogocorp@yahoo.com | I40: Thu 9:30 PM | J40: - AR BasedSpoke to Adnan the owner said they do NGS PGX CGX have medicare and serve nationwide said we should speak tmrw to nadeem the decison maker at 1.30 cst 9.30 our time -selene 2/4 - spoke to adnan said nadeem will be availble after 30 min will cb by then -2/5 | K40: DR NAdeem - approved CMS he was asking about percentage - address / contact info - upfront payment is a nono - 96 plate sample to do it together / 3 to 4 weeks after the report are out / 5 to 6 weeks to get paid - he is not working with TMS and RCE - W2 as an employee / - 35% - he was engaged with an egyptian girl and he knows alot of egyptian | M40: 46085.973 | O40: FALSE | Q40: 1922852169
...

Sheet Contract Sent
A1: SUB | B1: Opener | C1: Status | D1: Date Added | E1: Company Name | F1: Authorized Person | G1: Phone | H1: EMAIL | I1: Meeting Time | J1: Opener Summary | K1: George's Notes | L1: Auto Scheduler | M1: Last Call | N1: Action | O1: Checkbox | P1: Log | Q1: NPI
A2: ORT+CGM | B2: Ben | C2: Contract Sent | D2: 45554 | E2: Aa Medical Supply Inc | F2: Richard Yousif | G2: 586-933-6565 | H2: richard@aamedsupplies.com | K2: He is on vacation now, he will be back to the office next Monday 6/10/26 8:14 (jimmy) Left him a message on whatsapp said he's in the hospital 🤦‍♂️ - ben, he said that he is in a vacation and he will call me back _ George 03/26/2026 wants 3 agents to start with | M2: 46183.842 | O2: FALSE | P2: wants 3 agents to start with | Q2: 1053817924
A3: IMMUNE | B3: Selene | C3: Contract Sent | D3: 45944 | E3: DIAGNOSTIC SOLUTIONS | F3: Jessica Wilks | G3: 325-222-0621 | H3: jessicawilks@mediplus1.com | I3: Wed 5:00PM | J3: Jessica Wilks (Office Manager) - TX Based accepts medicare patients from other states works on PGX sent email meeting 5pm our time wed 10/14 - tried to find another number its discoonected | K3: NA left a VM (jimmy) 6/10/26 8:16 wants an email and to see the draft and the Contract sent an email follow up tomorrow, left a voice mail , left a voice mail | M3: 46183.844 | O3: FALSE | P3: no answer | Q3: 1396419933
A4: ORT | B4: Selene | C4: Contract Sent | D4: 46008 | E4: SHAPIRO Z ENTERPRISE INCORPORATED | F4: Zinoviy Eduardovich Shapiro | G4: 440-461-2648/440-278-0793 mr shapiro number | H4: alinamedicalsupply@gmail.com | I4: Thu 6:00 PM | J4: OH Based , Medicare liscenced, Ships all states meeting Thursday 11am EST 6 pm our time 12/15 | K4: He said that our price is very high, I tild him we can a gree on a lower budget and told me to say what he has in mind. Called him to connect him with George, but he did not answer. 6/10/26 8:25 He said to reschedule to monday 2 pm est, Doc 02/04/2026, left a voice mail shapiro wanted to review the prices and the contract and respond back to us, call back next wednesday same time 1/29, friday 5:30 same time , he wants some calculations to be sent to know whether it will be profitable to him or not Send him the price list one more time with examples what would be the case if he recieved 5-7 patients a week and what is expected in return , Calcucate Net profit Or ROI ( return on investment) , Avg Reimbursements - (Our cost + cost of the item ) = Net profit sent the email ill call tomorrow - ben He said he is currently interested in working for cpap /bipap /wound supply /cathethers /pure suply will give acb friday 7/29 | M4: 46232.744 | O4: FALSE | P4: no answer | Q4: 1518216126
A5: Lymphadema | B5: Selene | C5: Contract Sent | D5: 45979 | E5: SV MEDICAL SOLUTIONS INC | F5: Vanik Meliksetyan | G5: 929-556-3030 / | H5: SVMEDICALSOLUTIONSINC@gmail.com | I5: Wed 7:00PM | J5: NY based , Medicare liscenced , ships all states supplies lymph wraps interested to know more and he wanted to know about prices too meeting next wed at 5pm our time 10 am est 11/13 - said to give acb fri thats when he will be availble 1/7 - They said he is in the broklyn office cb next mon 2/5 | K5: He is on pause, he should be ready back by the end of june or by the first week of july asked for a call back by then (jimmy) 6/10/26 8:29 Really good Calliber , He wants us to send him the Cataelogue from sgivaris and the contracrt if we didn't already send him and he also wants to see how many patients can we send monthly voice mail 12/09/2025 left a voice mail , he is in vacation, left a message with his assistant and he will let him know call back in a week guy moved to another location, gatekeeper did not want to give me his phone told me to send an email - ben , so i called him and he is changing stores and it will take him a month to be able to work with anyone cb 4/12 he is waiting to complete the merge in the broklyn location , he took my numder and he would give me a call back / call back on monday Still no liscence cb at the end of august 7/24 | M5: 46227.927 | O5: FALSE | P5: he is waiting to complete the merge in the broklyn location , he took my numder and he would give me a call back | Q5: 1750183372
A6: ORT + Lymphedema | B6: Jane | C6: Contract Sent | D6: 46009 | E6: SAN BENITO RX LLC | F6: Oscar (biller) | G6: 956-399-2453 ext 304 | H6: frysdme311@gmail.com / oscarmeza80513@yahoo.com | I6: Thu 8:00 PM | J6: Tx based , medicare licensed, oscar is the biller handels every thing ,he is not sure if he can ship to all staes but interested to do that , supply ort and lymphedema, meeting 8 pm | K6: Call back Friday 12:00 pm He can onl bill for specific states. Oscar said to send him all the details with the pricing and he will discuss it with the owner and he asked if we can call him tomorrow 1 pm ( his time ) sent it again prices 1/9, he said he received it and will call us back this week, waiting for a call back ( george : 02/25/2026) he will check with the owner a good time for him to get to the meeting (propably will not go for it ) | M6: 46183.857 | O6: FALSE | P6: oscar is always not available | Q6: 1851139034
A7: ORT | B7: Jane | C7: Contract Sent | D7: 46027 | E7: GREAT HELP MEDICAL SUPPLY LLC | F7: Uzor | G7: 202-779-4560 | H7: greathelpmedicalsupplyllc@gmail.com | I7: Mon 5:00PM | J7: Md based, supply ort, medical liscensed ,he said he can ship allstates, but not sure when checked , meeting today 10 pm | K7: he has talk to his Partner, /sample + recordings + pricing + contract / DOC 01/09/2025 hanged up on me didnt have time to look,schedule a meeting next week 7:30 phone call - ben | M7: 46084.82 | O7: FALSE | Q7: 1669236436
A8: ORT+CGM+LYMPH W | B8: Ben | C8: Contract Sent | D8: 46031 | E8: STEMLYFT PARTNERS LLC | F8: GERARD MOHAMMED | G8: 832-656-4410 | H8: jmohammed@wellness1stpharmacy.com | I8: Fri 9:30 PM | J8: Jerry's the husband (i think) TX Based, Part B nationwide, the works | K8: NA left a VM 6/10/26 8:49 send the contract and the pricing ( for CGM ) , he is also interested in the braces 01/30/2025, he saw the price list and the reimbursements and he would give me a call back in an hour and also i could contact him on whats app daughter is sick - ben 2/27 - VM | M8: 46183.867 | O8: FALSE | P8: follow up on tuesday 9:00 pm our time to see if he is credentialed to do Orthopedic braces, if he is he can start right away | Q8: 1396414199
A9: ORT | B9: Selene | C9: Contract Sent | D9: 46041 | E9: FIRST CHOICE ORTHOTICS PROSTHETICS AND DME | F9: JAMAR WILLIAMS | G9: 810-282-8323 | H9: roc2723@gmail.com | I9: Tue 9:30PM | J9: - MI Based, Medicare Liscenced Ships all states ORT meeting tmrw 9.30 our time 1/19 | K9: NA left a VM 6/10/26 8:53 he is interested in doing the braces he wants to review the document and then we can call back 2:00 pm , he wants a contract the price list and the palmetto states where he could know which states can he work in, he wants to talk on saturday, he said he will call me back after 45 min , he will call me back after he recieve some money , he hanged up on me and sent me to the voice mail , - He was busy he said to give him a cb later3/3 | M9: 46183.869 | O9: FALSE | P9: no answer | Q9: 1780324830
A10: ORT+CGM | B10: Russ | C10: Contract Sent | D10: 46052 | E10: ORTHOTIC & PROSTHETIC ARTS | F10: ALTAGRACIA PENA-ATRISTAIN | G10: 845-459-0212 | H10: Nidia@ORTHOTICPROSTHETICARTS.Com | I10: WED 7:00 PM | K10: NA left a VM 6/10/26 8:57 Nidia is out on the field, be back tmrw - ben | M10: 46183.872 | O10: FALSE | Q10: 1649919010
A11: ORT | B11: Selene | C11: Contract Sent | D11: 46006 | E11: EXPO MEDICAL SUPPLY LLC | F11: SHARDAE KNIPS | G11: 305-336-1809 | H11: SHARDAE@EXPOMEDICALSUPPLY.COM | I11: Tue 10:00PM | J11: FL Based , Medicare, Ships all states meeting tuesday 3pm EST 10 pm our time 12/15 -Still didnt get Medicare CB at the End of Feb -selene 1/29 | K11: She said she never got the contract and wants a call back after 30 mins 6/10/26 9:08 more interested in CGM , needs better pricing , Might be interested in getting 2 agents 1/20/2025 she had to redo her accrediation, she is waiting for this to happen by the end of march | M11: 46183.896 | O11: FALSE | P11: she is interested to get around 15 patient a month then 40 patients next month with discounted price, she has an estimate for two weeks , waiting for the suspension to end upon accredidation because of the BOC , follow on thursday 9:30 our time, do a calender invite and ask about the good states that she can work with / she still didn't have an updte from medicare about her license | Q11: 1184352965
A12: ORT+CGM | B12: Ben | C12: Contract Sent | D12: 46077 | E12: STARMONET ESSENTIALS LLC | F12: DAVID SHAHZAD | G12: 314-656-6510 | H12: hxdavid1@gmail.com | I12: WED 7:00 PM | J12: MO Based, Dropshipping Medicare B | K12: He said that he is still in process of finishing his papers and asked me to call back after 2 weeks 6/10/26 9:30 he wants the Price list + avg Reimbursments + contract for BOth ORT & CGM , call back next thursday busy now didn't see the paperwork will call is (cb in 10 days if he didnt call) - ben | M12: 46240.888 | O12: FALSE | P12: call back in may | Q12: 1578352183
A13: ORT | B13: Selene | C13: Contract Sent | D13: 46084 | E13: MED SUPPLIES EXPRESS INC | F13: Mbaukwu U Anaba | G13: 678-377-5660 | H13: support@medsuppliesincs.com | I13: WED 5:00 PM | J13: GA Based, Medicare liscenced , Nationwide ORT said she wants a call meeting at 10 am est 5 pm our time -selene 3/3 - She said she is very busy during the day but she said 15 min before closing time is more suitable for her she said to call her tmrw at 1.45 our time -selene 3/16 | K13: Tomorrow 11:00 am EST she does not understand how to by agent and she said that the price is so high per prescription agreed on a meeting tomorrow 6/10/26 10:03 send the price list + contact and she will reply to the email about a good time for a followup call , she said that she didn't set an exact time with selene , she had a walk in so she asked to call her later 03/13/2026, 06/22/2026 she wants to approve the order first , new Template for ORT + contract + she only wants to work in GA , reschedule on monday | M13: 46198.756 | O13: FALSE | P13: no answer | Q13: 1619088796
A14: ORT+CGM | B14: Jane | C14: Contract Sent | D14: 46086 | E14: PADEK HOLDINGS LLC | F14: PRINCE AYODELE ADEKOYA | G14: 240-731-3766 | H14: prince@padekhealth.com / padek.healthcare@gmail.com | I14: Tue 8:00 PM | J14: MD based supply ort,cgm, ship allstates , medicasre liecned sent email,meeting tuesday | K14: NA vm is full 6/10/26 10:17 he has two other locations, he is only problem is to convince him to do an upfront payment send price list for ort & CGM devices and a contract , they will respond back with an email 06/30/2026 just talked to him right now, send him the marketing template for ort and CGM and we will talk to him at the end of the day or tomorrow, send the email and remember to call him to ask him if he reviewed the document today | M14: 46203.792 | O14: FALSE | P14: no answer | Q14: 1326912833
A15: ORT + Lymphedema | B15: Jimmy | C15: Contract Sent | D15: 46043 | E15: MERCY MEDICAL SUPPLIES LLC | F15: DONNA M CHANG | G15: 904-476-3305 | H15: suppliesMERCYMEDICAL@gmail.com | I15: FRI 7:00 PM | J15: - FL Based, Medicare Liscenced Ships nation wide | K15: NA 6/10/26 10:44 I called her again she apolozied for not showing up, she said her brother died, and she had a lot going on with her now, we a greed on a reset next WED 11/03 11:30 Her time 6:30 our time 3/4/26 10:22 She did not show up 2/4/26 8:30 1 pm fl NA 1/27/26 7:24 She did not answer 1/26/26 7:22 "Mail sent and meeting set She still at the beggining of running the business asked me for the mail and a meeting next monday at 12 pm suppliesMERCYMEDICAL@gmail.com " she didn't show up in the meeting | M15: 46183.946 | P15: no answer | Q15: 1912706565
A16: IMMUNE | B16: Jane | C16: Contract Sent | D16: 46147 | E16: GENE MATRIX LLC | F16: TAREK YOUNIS/ Lammy | G16: lammy no. 7732170877 office 847-302-9668/ tarek no 312-998-9275 | H16: lammy@genematrix.io , tarek@genematrix.io | I16: FRI 7:00 PM | J16: IL based, lammy called one of the desicion maker, saide the do ngs and pgx and has the machine, bill medicare and accept pt allstates, meeting on friday 11pm cst | K16: next meeting Monday 11:00 am EST (add mike to the meeting) , I spoke to tarek younis , he said that he already have a contract with hospitals and clinics for pgx doing 4000 Sample, and he can accept around 25 patients immuno and another 25-50 patient Cancer , he is interested but what i am afraid of since he already got this volume it wouldn't make sense for him to pay alot of many for extra samples,, MEETING NEXT UESDAY, WILL SEND THE MARKETING PLAN+ CONTRACT | M16: 46177.819 | O16: FALSE | Q16: 1225729312
A17: ORT+CGM | B17: Jane | C17: Contract Sent | D17: 46161 | E17: MTS DIRECT INC | F17: VICTORIA GATLIN | G17: 708-252-1958 | H17: v.gatling@yahoo.com | I17: Wed 10:00 PM | J17: IL based, supply ort and cgm, bill medicare part b, shipsnationwide, she can handle many pts .meeting tomw 10 pm | K17: Send her sample for both ort + CGM ( recordings ) + contract + pricing for both ort and CGM , she is interested and she wants to review these documents today and talk tomorrow at 10:00 am her time | M17: 46163.969 | Q17: 1972926012
A18: Lymphadema | B18: Selene | C18: Contract Sent | D18: 46175 | E18: SA MEDICAL SUPPLY | F18: SAUD ANWER | G18: 763-600-2858 | H18: saud.mittens@gmail.com | I18: THU 8:30 PM | J18: MN Based, Medicare liscenced, nationwide , will ask his team about the lymphedema supplier will join with his team to the meeting thu 6/3 - Still discusiing it with his team and will get back to us -selene 6/16 | K18: send the presentation + ask him about the capacity (how many patients he wants to receive 0 + states that he can cover + products that he wants to work with , so we can send him a marketing plan and a quotation and the contract and ask him in the email what would be a good time to talk again | M18: 46181.867 | Q18: 1821935933
A19: ORT+CGM | B19: Selene | C19: Contract Sent | D19: 46189 | E19: ORTHO PLUS LLC | F19: NETANEL SHIMONOV | G19: 347-707-8439 | H19: nathansvoice7@gmail.com | I19: Wed 9:00 PM | J19: NY Based , supply ORT CGM , Medicare Liscenced , supply locally but said will dropship nationwide if its worth it said give him a call tmrw our time 9 pm 6/16 | K19: it would be for another company that can do medicare , he has one called arial and sons , we talked for an hour, he is interested but he is facing an audit from medicare and his license might get revoked , send him the contract + presentation + marketing plan for orthopedic braces and marketing plan for CGM devices + some calculations that we did together over the meeting SEND GEORGE INFO CONTACT PHONE NUMBER / he is going to the accreditation process must be done in a month in order not medicare revoke them, he will only know 2-3 week , call back 07/10/2026, he wants to give him a call next week 07/07/2026 he needs to see if he would pass medicare inspection - Said that he was expecting a call from us regarding something profetable / no cgm no ort wants wound careor lymphedema8/3 | M19: 46237.939 | Q19: 1952136806
A20: CGM | B20: Selene | C20: Contract Sent | D20: 46182 | E20: JILANI MEDICAL | F20: Usman Jilani | G20: 773-931-7286 | H20: info@jilanimedical.com | I20: Wed 12:00 PM | J20: - IL Based, wants to really work with PPO BlueCross Blueshield and humana for CGM he wanted this for a really long time was interested to talk about it wants email and meeting wed 12 am -selene 6/9, products | K20: humana ppo, BCBS HMO and PPO , he wants to start with BCBS in illinois with a set budget for ORT and CGM, he will do a trial of a certain amount for the optin data for both campaigns so he wants us to send him an invoice and a contract called jilani siad to resend the the invoice and he wants bcbs and humana 7/29 | M20: 46232.785 | Q20: 1427679182
A21: Lab | B21: Jane | C21: Contract Sent | D21: 46234 | E21: GSB DIAGNOSTICS LLC | F21: Steven Likos | G21: 610-909-7757 | H21: slikos@gsbdiagnostics.com | I21: Mon 9:00 PM | J21: Fl based, they do ngs, pgx, uti, sti, gi, cgx, respiratory panel and wound care , can bill medicare, accept allstates except ca, ny , pa, nevada , he was interested into do all test with small starter, spoke about our up front payment , for flat fee example of our starter package for the uti only he said it was reinbersment in fl is lower than usual last couple of months, i told him there is pts from other states and will get higher reinbersments usually , he was interested to have google meet video meeting and speak face to face. | K21: george did explained and reassured him again after our last call, he is interested and wantto do busniess with us will inform his partners and will get back to us in 2 weeks maxi, an will get back to us and said we would might try you out, his partner just cam on saturday, and said will get an update by end of the week. | M21: 46251.884
A22: IMMUNE | B22: Jane | C22: Contract Sent | D22: 46230 | E22: DIRECT DIAGNOSTIC LABORATORY LLC | F22: RICHARD ELLIOTT | G22: 404-435-9685 | H22: richard@rasmedicalsolution.com | I22: Tue 9:30 PM | J22: Tx based do uti, pgx, molecular test and other genetic testing , bill medicare, accept pt all states,meeting tomw | K22: he has two labs GA and TX,HE CAN DO IMMUNE WITH PARTNERING OTHER LABS, CAN PROVIDE UTI, PGX AND STI IN HOUSE, MEDICARE PTS, BUT AFRAID OF TELE MEDICINE HE THINKS IT RISCKY,PREFER PCP , BUT WILL SEND HIM OUR SAMPLE OF PGX TELE MEDICINE IF COMPLIANT WITH H IM WILL DO BOTH MODULE, AND WILL SEND ROUGH MARKETING PLAN FOR ALL THREE TEST, the just saw it and will review it will reply to us back, still didnt review it yet, he still insisting on having a refrence labs who worked with us with telehealth module, so he can work with us | M22: 46251.884
A23: IMMUNE | B23: Jane | C23: Contract Sent | D23: 46120 | E23: BIOLIFE DIAGNOSTICS INC | F23: HUSSEIN HICHAM ABUJAJEH | G23: 314-750-5504 | H23: info@biolifemanagement.com | I23: Fri 9:00 PM | J23: Mi based, do ngs test and have the machine, medicare liscensed and accept pt from allstates, meeting tomw 5 pm | K23: mike spoke with him , he explained all the process and he wanted to review the email again and meeting on monday for follow up same time 4/9, he will send email to reschedule for follow up meeeting now he is busy with pts and have bad network, he called yesturday and reschedule today meeting , he wanted to know the prices after reviewed the email. i called him if he is currently doing the uti testing, he said yes asked to send email and booked meeting on friday 9 pm our time, he wants 50per week, but we told him we can do 25 per week,aka 100 month , will calculate it for him and get him a price and send it with contract. and schedeule a meeting on tuesday on thursday 9 pm our time, he spoke with mike and said the uti dont make sense with him , so will chek if he can do immune and pgx, we sent him the sample of immune and pgx prescription. | M23: 46237.797 | O23: FALSE | Q23: 1467346718
A24: ORT+CGM | B24: Selene | C24: Contract Sent | D24: 46205 | E24: CORE COMFORT MEDICAL SUPPLIES | F24: WASEEM KHAN | G24: 434-250-1675 | H24: waseem93@gmail.com | I24: Tue 8:30 PM | J24: FL Based, PPO , ORT .CGM said they can dropship nationwide , never done marketing but interested to learn more about it said wants meeting with his team on tueday 8.30 ourt time -selene 7/2 | K24: Meeting attended by mike send marketing plans, ORT CGM samples, Contract , they will review it and will reach out to us and i can follow up with them on mon 7/8 left a vm 7/16 - spoke to wassem said he really liked the marketing plan but he wants to figure things out on his side and will recah out to us said he will get back to us this week and agreed for me to reach out on him at mon 7/28 - meeting finalizing thursday at 8.30 our time he works with most ppo insurances humana, bcbs, united, wants to start with one agent and start with cgm asked about if we rae w2 i said we are w8 and its upfront payment 8/3 He said that he is interested in working with us and he wants to start in september 8/17 | M24: 46251.719 | Q24: 1336087469
A25: IMMUNE | B25: Selene | C25: Contract Sent | D25: 46043 | E25: EIV DIAGNOSTICS LLC | F25: MUHAMMAD IRFAN KHAN | G25: (559) 704-8024 | H25: irfan@eivdiagnostics.com | I25: Wed 11:00 PM | J25: CA based , accepts nationwide medicare patients provides immune genetic testing said to call him today 11 our time -selene 1/8 | K25: wednesday 11:00 pm he wants to do some duediligence to check if everything checks out, he is kinda skyptical and not very sure that if he did this he will get paid from medicare but we can do a follow up meeting on the 27th 11:00 pm , Doc 01/21/2025 working on stuff for the testing, talking to vendors, working on the panel, once he's ready he'll give us a call.spoke to him said he wants to get the z code approval for billing and it takes time 4/9 said cb 15th of june 6/2 - told him about the uti and pgx said hes interested and meeting tmrw 7/20 - Meeting follow up with george irfan said that california reimbursment is low and require z code so sends samples out of state in medicare ,he prefers cash pay, but we agreed on targeted insurance etna bcbs for CA he said our prices are high but george is willing to negionate follow up august 10 7/21 Mike spoke to him and said he has z code issues turns out its not an isuue but we have to convince him we sent him everything and i will call him to ask if he reviewed the codes and ask him which test doesnt need the z codes 8/12 | M25: 46246.898 | O25: FALSE | Q25: 1912529157
A26: IMMUNE | B26: Selene | C26: Contract Sent | D26: 45943 | E26: GENEWELL LABS LLC | F26: TARIQ HAFEEZ | G26: 404-617-8550 | H26: TARIQ@GENEWELLLABS.COM | I26: Tues 7:00PM | J26: Accept Medicare Nationwide , TX Based , Do GENETIC Testing PGX CGX MEETING SAT 5 PM OUR TIME 10/13 Meeting will be changed to Tuesday 11 cst 7 pm our time | K26: Another meeting on Wed 4 pm CST send contract Interested in UTI, STI ,PGX and Immundefiency test / covid ( influenza A ,b ) RSV , meeting tuesday 11:00 am, SAID WILL START ON FEB, forward to an automatic voice system , forwarded to Automatic voice message 02/25/2026 - Spoke to Mr Hafeez he said that he is busy with projects related to the world cup he said that when he is ready he will give us acall he couldnt give us a time to give him a cb selene 2/25 , voice mail meeting july 30th 11 am cst 7/20/ marketing plan He does immune ,pgx,uti get gets 35 to 40 samples week uti and 10 samples per week pgx we decided to stick to UTI calculated reimbursemts and i told him to discuss it with his biller and to read contract with lawyer he had a bit concerns on price and wether we will be commited or not siad he is applying CA and NY liscence to work therer sent prices contarct and samples follow up next wed 1.30 his time 7/30 He said he reviewed the contarct and the prices and discussed it with his biller briefly he said that he will discuss it in detail with his lawyer and we will have next meeting thursday 8/5 | M26: 46239.909 | O26: FALSE | Q26: 1952156622
A27: ORT+CGM | B27: Selene | C27: Contract Sent | D27: 46234 | E27: VITALCARE ESSENTIAL SUPPLIES CORP | F27: SYED SHAH | G27: 646-567-8371 | H27: vitalcaresuppliescorp@gmail.com | I27: Tue 6:00 PM | J27: NY Based ,supply ORT, CGM ,Mediacre liscenced ,supply locally said he does marketing himself but interested to know more said to give him a call at 11 am his time on Tuesday 7/31 | K27: Interested wants to focus on ORT he is interested to expand nationwide and will look into it .Send him prices ,contract,suppliers,and codes he said he will check the reimbursment and everything and we will speak again with mike and dan next week | M27: 46248.891 | Q27: 1225995830
A28: ORT+CGM | B28: Selene | C28: Contract Sent | D28: 46245 | E28: GRAJAG LLC | F28: RAJA GUL | G28: 713-382-7695 | H28: grajagllc84@gmail.com | I28: Wed 8:30 PM | J28: TX Based ,supply ORT, CGM ,Mediacre liscenced and PPO ,ships nationwide ,interested to know more said to give him a call at 8.30 pm our time 8/11 | K28: Sent him marketing plan and contract and CGM ORT samples said he will review it and we will touch base tommrow (ask him again about marketing ,direct him to CGM ,ask him when he would like to start and states) - He said he will start with CGM starter pack we iwll sedn him the contarct and i will call tmrw to have an onboarding meeting with mike and if its ok we will send the invoice after the meeting - Onboarding meeting set on Tuesday 7 pm our time 8/14 | M28: 46248.902 | Q28: 1306788872
A29: Lab | B29: Selene | C29: Contract Sent | D29: 46241 | E29: UNITED DOCTORS LAB INC | F29: Tony (Manager) | G29: 872-226-0303 | H29: Contact@chicagopath.com | I29: THU 8:00 PM | J29: IL Based, accept nationwide medicare patients does PGX,UTI test meeting Thursday 8.00 pm 8/7 | K29: He only works UTI only said he wants to try out our samples explained our entire process and he said that he will review documents and will get back to us cb next week to confirm meeting time 8/13 he said he will review everything folow up next tuesday 2 pm 8/19 | M29: 46253.782 | Q29: 1891511309

Sheet Invoice Sent
A1: SUB | B1: Opener | C1: Status | D1: Date Added | E1: Company Name | F1: Authorized Person | G1: Phone | H1: EMAIL | I1: Meeting Time | J1: Opener Summary | K1: George's Notes | L1: Auto Scheduler | M1: Last Call | N1: Action | O1: Checkbox | P1: Log | Q1: NPI
